[2025-02-17T01:27:48.017+0000] {local_task_job_runner.py:123} INFO - ::group::Pre task execution logs
[2025-02-17T01:27:48.026+0000] {taskinstance.py:2613} INFO - Dependencies all met for dep_context=non-requeueable deps ti=<TaskInstance: idp.fetch_from_mongo scheduled__2025-02-16T00:00:00+00:00 [queued]>
[2025-02-17T01:27:48.030+0000] {taskinstance.py:2613} INFO - Dependencies all met for dep_context=requeueable deps ti=<TaskInstance: idp.fetch_from_mongo scheduled__2025-02-16T00:00:00+00:00 [queued]>
[2025-02-17T01:27:48.030+0000] {taskinstance.py:2866} INFO - Starting attempt 1 of 2
[2025-02-17T01:27:48.036+0000] {taskinstance.py:2889} INFO - Executing <Task(PythonOperator): fetch_from_mongo> on 2025-02-16 00:00:00+00:00
[2025-02-17T01:27:48.056+0000] {warnings.py:112} WARNING - /home/***/.local/lib/python3.12/site-packages/***/task/task_runner/standard_task_runner.py:70: DeprecationWarning: This process (pid=17278) is multi-threaded, use of fork() may lead to deadlocks in the child.
  pid = os.fork()

[2025-02-17T01:27:48.059+0000] {standard_task_runner.py:72} INFO - Started process 17279 to run task
[2025-02-17T01:27:48.060+0000] {standard_task_runner.py:104} INFO - Running: ['***', 'tasks', 'run', 'idp', 'fetch_from_mongo', 'scheduled__2025-02-16T00:00:00+00:00', '--job-id', '327', '--raw', '--subdir', 'DAGS_FOLDER/idp.py', '--cfg-path', '/tmp/tmpobjopzv1']
[2025-02-17T01:27:48.061+0000] {standard_task_runner.py:105} INFO - Job 327: Subtask fetch_from_mongo
[2025-02-17T01:27:48.116+0000] {task_command.py:467} INFO - Running <TaskInstance: idp.fetch_from_mongo scheduled__2025-02-16T00:00:00+00:00 [running]> on host 3aa1f743f988
[2025-02-17T01:27:48.200+0000] {taskinstance.py:3132} INFO - Exporting env vars: AIRFLOW_CTX_DAG_OWNER='***' AIRFLOW_CTX_DAG_ID='idp' AIRFLOW_CTX_TASK_ID='fetch_from_mongo' AIRFLOW_CTX_EXECUTION_DATE='2025-02-16T00:00:00+00:00' AIRFLOW_CTX_TRY_NUMBER='1' AIRFLOW_CTX_DAG_RUN_ID='scheduled__2025-02-16T00:00:00+00:00'
[2025-02-17T01:27:48.202+0000] {logging_mixin.py:190} INFO - Task instance is in running state
[2025-02-17T01:27:48.202+0000] {logging_mixin.py:190} INFO -  Previous state of the Task instance: queued
[2025-02-17T01:27:48.202+0000] {logging_mixin.py:190} INFO - Current task name:fetch_from_mongo state:running start_date:2025-02-17 01:27:48.026880+00:00
[2025-02-17T01:27:48.203+0000] {logging_mixin.py:190} INFO - Dag name:idp and current dag run status:running
[2025-02-17T01:27:48.203+0000] {taskinstance.py:731} INFO - ::endgroup::
[2025-02-17T01:27:48.204+0000] {logging_mixin.py:190} INFO - Received message from XCom: 
[2025-02-17T01:27:50.493+0000] {taskinstance.py:3311} ERROR - Task failed with exception
Traceback (most recent call last):
  File "/opt/airflow/dags/idp.py", line 116, in fetch_from_mongo
    client = MongoClient(uri)
             ^^^^^^^^^^^^^^^^
  File "/home/airflow/.local/lib/python3.12/site-packages/pymongo/synchronous/mongo_client.py", line 784, in __init__
    res = uri_parser.parse_uri(
          ^^^^^^^^^^^^^^^^^^^^^
  File "/home/airflow/.local/lib/python3.12/site-packages/pymongo/uri_parser.py", line 558, in parse_uri
    nodes = dns_resolver.get_hosts()
            ^^^^^^^^^^^^^^^^^^^^^^^^
  File "/home/airflow/.local/lib/python3.12/site-packages/pymongo/srv_resolver.py", line 141, in get_hosts
    _, nodes = self._get_srv_response_and_hosts(True)
               ^^^^^^^^^^^^^^^^^^^^^^^^^^^^^^^^^^^^^^
  File "/home/airflow/.local/lib/python3.12/site-packages/pymongo/srv_resolver.py", line 120, in _get_srv_response_and_hosts
    results = self._resolve_uri(encapsulate_errors)
              ^^^^^^^^^^^^^^^^^^^^^^^^^^^^^^^^^^^^^
  File "/home/airflow/.local/lib/python3.12/site-packages/pymongo/srv_resolver.py", line 114, in _resolve_uri
    raise ConfigurationError(str(exc)) from None
pymongo.errors.ConfigurationError: The DNS query name does not exist: _mongodb._tcp.cluster0.ejwm7.mongodb.net.

During handling of the above exception, another exception occurred:

Traceback (most recent call last):
  File "/opt/airflow/dags/idp.py", line 124, in fetch_from_mongo
    raise Exception(f"The following error occurred: {str(e)}")
Exception: The following error occurred: The DNS query name does not exist: _mongodb._tcp.cluster0.ejwm7.mongodb.net.

During handling of the above exception, another exception occurred:

Traceback (most recent call last):
  File "/home/airflow/.local/lib/python3.12/site-packages/airflow/models/taskinstance.py", line 767, in _execute_task
    result = _execute_callable(context=context, **execute_callable_kwargs)
             ^^^^^^^^^^^^^^^^^^^^^^^^^^^^^^^^^^^^^^^^^^^^^^^^^^^^^^^^^^^^^
  File "/home/airflow/.local/lib/python3.12/site-packages/airflow/models/taskinstance.py", line 733, in _execute_callable
    return ExecutionCallableRunner(
           ^^^^^^^^^^^^^^^^^^^^^^^^
  File "/home/airflow/.local/lib/python3.12/site-packages/airflow/utils/operator_helpers.py", line 252, in run
    return self.func(*args, **kwargs)
           ^^^^^^^^^^^^^^^^^^^^^^^^^^
  File "/home/airflow/.local/lib/python3.12/site-packages/airflow/models/baseoperator.py", line 422, in wrapper
    return func(self, *args, **kwargs)
           ^^^^^^^^^^^^^^^^^^^^^^^^^^^
  File "/home/airflow/.local/lib/python3.12/site-packages/airflow/operators/python.py", line 238, in execute
    return_value = self.execute_callable()
                   ^^^^^^^^^^^^^^^^^^^^^^^
  File "/home/airflow/.local/lib/python3.12/site-packages/airflow/operators/python.py", line 256, in execute_callable
    return runner.run(*self.op_args, **self.op_kwargs)
           ^^^^^^^^^^^^^^^^^^^^^^^^^^^^^^^^^^^^^^^^^^^
  File "/home/airflow/.local/lib/python3.12/site-packages/airflow/utils/operator_helpers.py", line 252, in run
    return self.func(*args, **kwargs)
           ^^^^^^^^^^^^^^^^^^^^^^^^^^
  File "/opt/airflow/dags/idp.py", line 127, in fetch_from_mongo
    client.close()
    ^^^^^^
UnboundLocalError: cannot access local variable 'client' where it is not associated with a value
[2025-02-17T01:27:50.575+0000] {logging_mixin.py:190} INFO - Task instance in failure state
[2025-02-17T01:27:50.575+0000] {logging_mixin.py:190} INFO - Task start:2025-02-17 01:27:48.026880+00:00 end:2025-02-17 01:27:50.570734+00:00 duration:2.543854
[2025-02-17T01:27:50.576+0000] {logging_mixin.py:190} INFO - Task:<Task(PythonOperator): fetch_from_mongo> dag:<DAG: idp> dagrun:<DagRun idp @ 2025-02-16 00:00:00+00:00: scheduled__2025-02-16T00:00:00+00:00, state:running, queued_at: 2025-02-17 00:08:01.799450+00:00. externally triggered: False>
[2025-02-17T01:27:50.576+0000] {logging_mixin.py:190} INFO - Failure caused by cannot access local variable 'client' where it is not associated with a value
[2025-02-17T01:27:50.576+0000] {taskinstance.py:1225} INFO - Marking task as UP_FOR_RETRY. dag_id=idp, task_id=fetch_from_mongo, run_id=scheduled__2025-02-16T00:00:00+00:00, execution_date=20250216T000000, start_date=20250217T012748, end_date=20250217T012750
[2025-02-17T01:27:50.595+0000] {taskinstance.py:340} INFO - ::group::Post task execution logs
[2025-02-17T01:27:50.596+0000] {standard_task_runner.py:124} ERROR - Failed to execute job 327 for task fetch_from_mongo (cannot access local variable 'client' where it is not associated with a value; 17279)
Traceback (most recent call last):
  File "/opt/airflow/dags/idp.py", line 116, in fetch_from_mongo
    client = MongoClient(uri)
             ^^^^^^^^^^^^^^^^
  File "/home/airflow/.local/lib/python3.12/site-packages/pymongo/synchronous/mongo_client.py", line 784, in __init__
    res = uri_parser.parse_uri(
          ^^^^^^^^^^^^^^^^^^^^^
  File "/home/airflow/.local/lib/python3.12/site-packages/pymongo/uri_parser.py", line 558, in parse_uri
    nodes = dns_resolver.get_hosts()
            ^^^^^^^^^^^^^^^^^^^^^^^^
  File "/home/airflow/.local/lib/python3.12/site-packages/pymongo/srv_resolver.py", line 141, in get_hosts
    _, nodes = self._get_srv_response_and_hosts(True)
               ^^^^^^^^^^^^^^^^^^^^^^^^^^^^^^^^^^^^^^
  File "/home/airflow/.local/lib/python3.12/site-packages/pymongo/srv_resolver.py", line 120, in _get_srv_response_and_hosts
    results = self._resolve_uri(encapsulate_errors)
              ^^^^^^^^^^^^^^^^^^^^^^^^^^^^^^^^^^^^^
  File "/home/airflow/.local/lib/python3.12/site-packages/pymongo/srv_resolver.py", line 114, in _resolve_uri
    raise ConfigurationError(str(exc)) from None
pymongo.errors.ConfigurationError: The DNS query name does not exist: _mongodb._tcp.cluster0.ejwm7.mongodb.net.

During handling of the above exception, another exception occurred:

Traceback (most recent call last):
  File "/opt/airflow/dags/idp.py", line 124, in fetch_from_mongo
    raise Exception(f"The following error occurred: {str(e)}")
Exception: The following error occurred: The DNS query name does not exist: _mongodb._tcp.cluster0.ejwm7.mongodb.net.

During handling of the above exception, another exception occurred:

Traceback (most recent call last):
  File "/home/airflow/.local/lib/python3.12/site-packages/airflow/task/task_runner/standard_task_runner.py", line 117, in _start_by_fork
    ret = args.func(args, dag=self.dag)
          ^^^^^^^^^^^^^^^^^^^^^^^^^^^^^
  File "/home/airflow/.local/lib/python3.12/site-packages/airflow/cli/cli_config.py", line 49, in command
    return func(*args, **kwargs)
           ^^^^^^^^^^^^^^^^^^^^^
  File "/home/airflow/.local/lib/python3.12/site-packages/airflow/utils/cli.py", line 116, in wrapper
    return f(*args, **kwargs)
           ^^^^^^^^^^^^^^^^^^
  File "/home/airflow/.local/lib/python3.12/site-packages/airflow/cli/commands/task_command.py", line 483, in task_run
    task_return_code = _run_task_by_selected_method(args, _dag, ti)
                       ^^^^^^^^^^^^^^^^^^^^^^^^^^^^^^^^^^^^^^^^^^^^
  File "/home/airflow/.local/lib/python3.12/site-packages/airflow/cli/commands/task_command.py", line 256, in _run_task_by_selected_method
    return _run_raw_task(args, ti)
           ^^^^^^^^^^^^^^^^^^^^^^^
  File "/home/airflow/.local/lib/python3.12/site-packages/airflow/cli/commands/task_command.py", line 341, in _run_raw_task
    return ti._run_raw_task(
           ^^^^^^^^^^^^^^^^^
  File "/home/airflow/.local/lib/python3.12/site-packages/airflow/utils/session.py", line 97, in wrapper
    return func(*args, session=session, **kwargs)
           ^^^^^^^^^^^^^^^^^^^^^^^^^^^^^^^^^^^^^^
  File "/home/airflow/.local/lib/python3.12/site-packages/airflow/models/taskinstance.py", line 3005, in _run_raw_task
    return _run_raw_task(
           ^^^^^^^^^^^^^^
  File "/home/airflow/.local/lib/python3.12/site-packages/airflow/models/taskinstance.py", line 273, in _run_raw_task
    TaskInstance._execute_task_with_callbacks(
  File "/home/airflow/.local/lib/python3.12/site-packages/airflow/models/taskinstance.py", line 3159, in _execute_task_with_callbacks
    result = self._execute_task(context, task_orig)
             ^^^^^^^^^^^^^^^^^^^^^^^^^^^^^^^^^^^^^^
  File "/home/airflow/.local/lib/python3.12/site-packages/airflow/models/taskinstance.py", line 3183, in _execute_task
    return _execute_task(self, context, task_orig)
           ^^^^^^^^^^^^^^^^^^^^^^^^^^^^^^^^^^^^^^^
  File "/home/airflow/.local/lib/python3.12/site-packages/airflow/models/taskinstance.py", line 767, in _execute_task
    result = _execute_callable(context=context, **execute_callable_kwargs)
             ^^^^^^^^^^^^^^^^^^^^^^^^^^^^^^^^^^^^^^^^^^^^^^^^^^^^^^^^^^^^^
  File "/home/airflow/.local/lib/python3.12/site-packages/airflow/models/taskinstance.py", line 733, in _execute_callable
    return ExecutionCallableRunner(
           ^^^^^^^^^^^^^^^^^^^^^^^^
  File "/home/airflow/.local/lib/python3.12/site-packages/airflow/utils/operator_helpers.py", line 252, in run
    return self.func(*args, **kwargs)
           ^^^^^^^^^^^^^^^^^^^^^^^^^^
  File "/home/airflow/.local/lib/python3.12/site-packages/airflow/models/baseoperator.py", line 422, in wrapper
    return func(self, *args, **kwargs)
           ^^^^^^^^^^^^^^^^^^^^^^^^^^^
  File "/home/airflow/.local/lib/python3.12/site-packages/airflow/operators/python.py", line 238, in execute
    return_value = self.execute_callable()
                   ^^^^^^^^^^^^^^^^^^^^^^^
  File "/home/airflow/.local/lib/python3.12/site-packages/airflow/operators/python.py", line 256, in execute_callable
    return runner.run(*self.op_args, **self.op_kwargs)
           ^^^^^^^^^^^^^^^^^^^^^^^^^^^^^^^^^^^^^^^^^^^
  File "/home/airflow/.local/lib/python3.12/site-packages/airflow/utils/operator_helpers.py", line 252, in run
    return self.func(*args, **kwargs)
           ^^^^^^^^^^^^^^^^^^^^^^^^^^
  File "/opt/airflow/dags/idp.py", line 127, in fetch_from_mongo
    client.close()
    ^^^^^^
UnboundLocalError: cannot access local variable 'client' where it is not associated with a value
[2025-02-17T01:27:50.674+0000] {local_task_job_runner.py:266} INFO - Task exited with return code 1
[2025-02-17T01:27:50.727+0000] {taskinstance.py:3895} INFO - 0 downstream tasks scheduled from follow-on schedule check
[2025-02-17T01:27:50.729+0000] {local_task_job_runner.py:245} INFO - ::endgroup::
