[2025-02-23T10:56:11.536+0000] {local_task_job_runner.py:123} INFO - ::group::Pre task execution logs
[2025-02-23T10:56:11.633+0000] {taskinstance.py:2613} INFO - Dependencies all met for dep_context=non-requeueable deps ti=<TaskInstance: idp.send_notification manual__2025-02-23T10:48:28.568919+00:00 [queued]>
[2025-02-23T10:56:11.663+0000] {taskinstance.py:2613} INFO - Dependencies all met for dep_context=requeueable deps ti=<TaskInstance: idp.send_notification manual__2025-02-23T10:48:28.568919+00:00 [queued]>
[2025-02-23T10:56:11.666+0000] {taskinstance.py:2866} INFO - Starting attempt 2 of 2
[2025-02-23T10:56:11.723+0000] {taskinstance.py:2889} INFO - Executing <Task(PythonOperator): send_notification> on 2025-02-23 10:48:28.568919+00:00
[2025-02-23T10:56:11.792+0000] {warnings.py:112} WARNING - /home/***/.local/lib/python3.12/site-packages/***/task/task_runner/standard_task_runner.py:70: DeprecationWarning: This process (pid=2508) is multi-threaded, use of fork() may lead to deadlocks in the child.
  pid = os.fork()

[2025-02-23T10:56:11.835+0000] {standard_task_runner.py:72} INFO - Started process 2515 to run task
[2025-02-23T10:56:11.851+0000] {standard_task_runner.py:104} INFO - Running: ['***', 'tasks', 'run', 'idp', 'send_notification', 'manual__2025-02-23T10:48:28.568919+00:00', '--job-id', '394', '--raw', '--subdir', 'DAGS_FOLDER/idp.py', '--cfg-path', '/tmp/tmp14pd8x4b']
[2025-02-23T10:56:11.868+0000] {standard_task_runner.py:105} INFO - Job 394: Subtask send_notification
[2025-02-23T10:56:12.776+0000] {task_command.py:467} INFO - Running <TaskInstance: idp.send_notification manual__2025-02-23T10:48:28.568919+00:00 [running]> on host 9d363d0f65d2
[2025-02-23T10:56:13.365+0000] {taskinstance.py:3132} INFO - Exporting env vars: AIRFLOW_CTX_DAG_OWNER='***' AIRFLOW_CTX_DAG_ID='idp' AIRFLOW_CTX_TASK_ID='send_notification' AIRFLOW_CTX_EXECUTION_DATE='2025-02-23T10:48:28.568919+00:00' AIRFLOW_CTX_TRY_NUMBER='2' AIRFLOW_CTX_DAG_RUN_ID='manual__2025-02-23T10:48:28.568919+00:00'
[2025-02-23T10:56:13.388+0000] {logging_mixin.py:190} INFO - Task instance is in running state
[2025-02-23T10:56:13.392+0000] {logging_mixin.py:190} INFO -  Previous state of the Task instance: queued
[2025-02-23T10:56:13.406+0000] {logging_mixin.py:190} INFO - Current task name:send_notification state:running start_date:2025-02-23 10:56:11.637886+00:00
[2025-02-23T10:56:13.420+0000] {logging_mixin.py:190} INFO - Dag name:idp and current dag run status:running
[2025-02-23T10:56:13.425+0000] {taskinstance.py:731} INFO - ::endgroup::
[2025-02-23T10:56:14.008+0000] {logging_mixin.py:190} INFO - Retrying... HTTPConnectionPool(host='localhost', port=4000): Max retries exceeded with url: /socket.io/?transport=polling&EIO=4&t=1740308173.7475476 (Caused by NewConnectionError('<urllib3.connection.HTTPConnection object at 0xffff6282e7b0>: Failed to establish a new connection: [Errno 111] Connection refused'))
[2025-02-23T10:56:16.259+0000] {logging_mixin.py:190} INFO - Retrying... HTTPConnectionPool(host='localhost', port=4000): Max retries exceeded with url: /socket.io/?transport=polling&EIO=4&t=1740308176.0385478 (Caused by NewConnectionError('<urllib3.connection.HTTPConnection object at 0xffff627112b0>: Failed to establish a new connection: [Errno 111] Connection refused'))
[2025-02-23T10:56:18.602+0000] {logging_mixin.py:190} INFO - Retrying... HTTPConnectionPool(host='localhost', port=4000): Max retries exceeded with url: /socket.io/?transport=polling&EIO=4&t=1740308178.3204727 (Caused by NewConnectionError('<urllib3.connection.HTTPConnection object at 0xffff62711e20>: Failed to establish a new connection: [Errno 111] Connection refused'))
[2025-02-23T10:56:20.880+0000] {logging_mixin.py:190} INFO - Retrying... HTTPConnectionPool(host='localhost', port=4000): Max retries exceeded with url: /socket.io/?transport=polling&EIO=4&t=1740308180.7539496 (Caused by NewConnectionError('<urllib3.connection.HTTPConnection object at 0xffff629e3d10>: Failed to establish a new connection: [Errno 111] Connection refused'))
[2025-02-23T10:56:23.063+0000] {logging_mixin.py:190} INFO - Retrying... HTTPConnectionPool(host='localhost', port=4000): Max retries exceeded with url: /socket.io/?transport=polling&EIO=4&t=1740308182.905483 (Caused by NewConnectionError('<urllib3.connection.HTTPConnection object at 0xffff62711f10>: Failed to establish a new connection: [Errno 111] Connection refused'))
[2025-02-23T10:56:25.239+0000] {taskinstance.py:3311} ERROR - Task failed with exception
Traceback (most recent call last):
  File "/home/airflow/.local/lib/python3.12/site-packages/airflow/models/taskinstance.py", line 767, in _execute_task
    result = _execute_callable(context=context, **execute_callable_kwargs)
             ^^^^^^^^^^^^^^^^^^^^^^^^^^^^^^^^^^^^^^^^^^^^^^^^^^^^^^^^^^^^^
  File "/home/airflow/.local/lib/python3.12/site-packages/airflow/models/taskinstance.py", line 733, in _execute_callable
    return ExecutionCallableRunner(
           ^^^^^^^^^^^^^^^^^^^^^^^^
  File "/home/airflow/.local/lib/python3.12/site-packages/airflow/utils/operator_helpers.py", line 252, in run
    return self.func(*args, **kwargs)
           ^^^^^^^^^^^^^^^^^^^^^^^^^^
  File "/home/airflow/.local/lib/python3.12/site-packages/airflow/models/baseoperator.py", line 422, in wrapper
    return func(self, *args, **kwargs)
           ^^^^^^^^^^^^^^^^^^^^^^^^^^^
  File "/home/airflow/.local/lib/python3.12/site-packages/airflow/operators/python.py", line 238, in execute
    return_value = self.execute_callable()
                   ^^^^^^^^^^^^^^^^^^^^^^^
  File "/home/airflow/.local/lib/python3.12/site-packages/airflow/operators/python.py", line 256, in execute_callable
    return runner.run(*self.op_args, **self.op_kwargs)
           ^^^^^^^^^^^^^^^^^^^^^^^^^^^^^^^^^^^^^^^^^^^
  File "/home/airflow/.local/lib/python3.12/site-packages/airflow/utils/operator_helpers.py", line 252, in run
    return self.func(*args, **kwargs)
           ^^^^^^^^^^^^^^^^^^^^^^^^^^
  File "/opt/airflow/dags/idp.py", line 144, in send_notification
    sio.emit('notification', {'message': 'Your virtual machine is being created now'})
  File "/home/airflow/.local/lib/python3.12/site-packages/socketio/client.py", line 219, in emit
    raise exceptions.BadNamespaceError(
socketio.exceptions.BadNamespaceError: / is not a connected namespace.
[2025-02-23T10:56:27.047+0000] {logging_mixin.py:190} INFO - Task instance in failure state
[2025-02-23T10:56:27.081+0000] {logging_mixin.py:190} INFO - Task start:2025-02-23 10:56:11.637886+00:00 end:2025-02-23 10:56:27.035496+00:00 duration:15.39761
[2025-02-23T10:56:27.086+0000] {logging_mixin.py:190} INFO - Task:<Task(PythonOperator): send_notification> dag:<DAG: idp> dagrun:<DagRun idp @ 2025-02-23 10:48:28.568919+00:00: manual__2025-02-23T10:48:28.568919+00:00, state:running, queued_at: 2025-02-23 10:48:28.894621+00:00. externally triggered: True>
[2025-02-23T10:56:27.091+0000] {logging_mixin.py:190} INFO - Failure caused by / is not a connected namespace.
[2025-02-23T10:56:27.093+0000] {taskinstance.py:1225} INFO - Marking task as FAILED. dag_id=idp, task_id=send_notification, run_id=manual__2025-02-23T10:48:28.568919+00:00, execution_date=20250223T104828, start_date=20250223T105611, end_date=20250223T105627
[2025-02-23T10:56:27.343+0000] {taskinstance.py:340} INFO - ::group::Post task execution logs
[2025-02-23T10:56:27.353+0000] {standard_task_runner.py:124} ERROR - Failed to execute job 394 for task send_notification (/ is not a connected namespace.; 2515)
Traceback (most recent call last):
  File "/home/airflow/.local/lib/python3.12/site-packages/airflow/task/task_runner/standard_task_runner.py", line 117, in _start_by_fork
    ret = args.func(args, dag=self.dag)
          ^^^^^^^^^^^^^^^^^^^^^^^^^^^^^
  File "/home/airflow/.local/lib/python3.12/site-packages/airflow/cli/cli_config.py", line 49, in command
    return func(*args, **kwargs)
           ^^^^^^^^^^^^^^^^^^^^^
  File "/home/airflow/.local/lib/python3.12/site-packages/airflow/utils/cli.py", line 116, in wrapper
    return f(*args, **kwargs)
           ^^^^^^^^^^^^^^^^^^
  File "/home/airflow/.local/lib/python3.12/site-packages/airflow/cli/commands/task_command.py", line 483, in task_run
    task_return_code = _run_task_by_selected_method(args, _dag, ti)
                       ^^^^^^^^^^^^^^^^^^^^^^^^^^^^^^^^^^^^^^^^^^^^
  File "/home/airflow/.local/lib/python3.12/site-packages/airflow/cli/commands/task_command.py", line 256, in _run_task_by_selected_method
    return _run_raw_task(args, ti)
           ^^^^^^^^^^^^^^^^^^^^^^^
  File "/home/airflow/.local/lib/python3.12/site-packages/airflow/cli/commands/task_command.py", line 341, in _run_raw_task
    return ti._run_raw_task(
           ^^^^^^^^^^^^^^^^^
  File "/home/airflow/.local/lib/python3.12/site-packages/airflow/utils/session.py", line 97, in wrapper
    return func(*args, session=session, **kwargs)
           ^^^^^^^^^^^^^^^^^^^^^^^^^^^^^^^^^^^^^^
  File "/home/airflow/.local/lib/python3.12/site-packages/airflow/models/taskinstance.py", line 3005, in _run_raw_task
    return _run_raw_task(
           ^^^^^^^^^^^^^^
  File "/home/airflow/.local/lib/python3.12/site-packages/airflow/models/taskinstance.py", line 273, in _run_raw_task
    TaskInstance._execute_task_with_callbacks(
  File "/home/airflow/.local/lib/python3.12/site-packages/airflow/models/taskinstance.py", line 3159, in _execute_task_with_callbacks
    result = self._execute_task(context, task_orig)
             ^^^^^^^^^^^^^^^^^^^^^^^^^^^^^^^^^^^^^^
  File "/home/airflow/.local/lib/python3.12/site-packages/airflow/models/taskinstance.py", line 3183, in _execute_task
    return _execute_task(self, context, task_orig)
           ^^^^^^^^^^^^^^^^^^^^^^^^^^^^^^^^^^^^^^^
  File "/home/airflow/.local/lib/python3.12/site-packages/airflow/models/taskinstance.py", line 767, in _execute_task
    result = _execute_callable(context=context, **execute_callable_kwargs)
             ^^^^^^^^^^^^^^^^^^^^^^^^^^^^^^^^^^^^^^^^^^^^^^^^^^^^^^^^^^^^^
  File "/home/airflow/.local/lib/python3.12/site-packages/airflow/models/taskinstance.py", line 733, in _execute_callable
    return ExecutionCallableRunner(
           ^^^^^^^^^^^^^^^^^^^^^^^^
  File "/home/airflow/.local/lib/python3.12/site-packages/airflow/utils/operator_helpers.py", line 252, in run
    return self.func(*args, **kwargs)
           ^^^^^^^^^^^^^^^^^^^^^^^^^^
  File "/home/airflow/.local/lib/python3.12/site-packages/airflow/models/baseoperator.py", line 422, in wrapper
    return func(self, *args, **kwargs)
           ^^^^^^^^^^^^^^^^^^^^^^^^^^^
  File "/home/airflow/.local/lib/python3.12/site-packages/airflow/operators/python.py", line 238, in execute
    return_value = self.execute_callable()
                   ^^^^^^^^^^^^^^^^^^^^^^^
  File "/home/airflow/.local/lib/python3.12/site-packages/airflow/operators/python.py", line 256, in execute_callable
    return runner.run(*self.op_args, **self.op_kwargs)
           ^^^^^^^^^^^^^^^^^^^^^^^^^^^^^^^^^^^^^^^^^^^
  File "/home/airflow/.local/lib/python3.12/site-packages/airflow/utils/operator_helpers.py", line 252, in run
    return self.func(*args, **kwargs)
           ^^^^^^^^^^^^^^^^^^^^^^^^^^
  File "/opt/airflow/dags/idp.py", line 144, in send_notification
    sio.emit('notification', {'message': 'Your virtual machine is being created now'})
  File "/home/airflow/.local/lib/python3.12/site-packages/socketio/client.py", line 219, in emit
    raise exceptions.BadNamespaceError(
socketio.exceptions.BadNamespaceError: / is not a connected namespace.
[2025-02-23T10:56:27.640+0000] {local_task_job_runner.py:266} INFO - Task exited with return code 1
[2025-02-23T10:56:29.881+0000] {taskinstance.py:3895} INFO - 0 downstream tasks scheduled from follow-on schedule check
[2025-02-23T10:56:29.984+0000] {local_task_job_runner.py:245} INFO - ::endgroup::
[2025-02-23T10:56:32.138+0000] {standard_task_runner.py:217} INFO - Process not found (most likely exited), stop collecting metrics
