[2025-02-23T10:49:56.967+0000] {local_task_job_runner.py:123} INFO - ::group::Pre task execution logs
[2025-02-23T10:49:57.101+0000] {taskinstance.py:2613} INFO - Dependencies all met for dep_context=non-requeueable deps ti=<TaskInstance: idp.send_notification manual__2025-02-23T10:48:28.568919+00:00 [queued]>
[2025-02-23T10:49:57.153+0000] {taskinstance.py:2613} INFO - Dependencies all met for dep_context=requeueable deps ti=<TaskInstance: idp.send_notification manual__2025-02-23T10:48:28.568919+00:00 [queued]>
[2025-02-23T10:49:57.154+0000] {taskinstance.py:2866} INFO - Starting attempt 1 of 2
[2025-02-23T10:49:57.312+0000] {taskinstance.py:2889} INFO - Executing <Task(PythonOperator): send_notification> on 2025-02-23 10:48:28.568919+00:00
[2025-02-23T10:49:57.441+0000] {warnings.py:112} WARNING - /home/***/.local/lib/python3.12/site-packages/***/task/task_runner/standard_task_runner.py:70: DeprecationWarning: This process (pid=2449) is multi-threaded, use of fork() may lead to deadlocks in the child.
  pid = os.fork()

[2025-02-23T10:49:57.457+0000] {standard_task_runner.py:104} INFO - Running: ['***', 'tasks', 'run', 'idp', 'send_notification', 'manual__2025-02-23T10:48:28.568919+00:00', '--job-id', '393', '--raw', '--subdir', 'DAGS_FOLDER/idp.py', '--cfg-path', '/tmp/tmpff0q6qam']
[2025-02-23T10:49:57.462+0000] {standard_task_runner.py:105} INFO - Job 393: Subtask send_notification
[2025-02-23T10:49:57.461+0000] {standard_task_runner.py:72} INFO - Started process 2450 to run task
[2025-02-23T10:49:57.702+0000] {task_command.py:467} INFO - Running <TaskInstance: idp.send_notification manual__2025-02-23T10:48:28.568919+00:00 [running]> on host 9d363d0f65d2
[2025-02-23T10:49:58.147+0000] {taskinstance.py:3132} INFO - Exporting env vars: AIRFLOW_CTX_DAG_OWNER='***' AIRFLOW_CTX_DAG_ID='idp' AIRFLOW_CTX_TASK_ID='send_notification' AIRFLOW_CTX_EXECUTION_DATE='2025-02-23T10:48:28.568919+00:00' AIRFLOW_CTX_TRY_NUMBER='1' AIRFLOW_CTX_DAG_RUN_ID='manual__2025-02-23T10:48:28.568919+00:00'
[2025-02-23T10:49:58.184+0000] {logging_mixin.py:190} INFO - Task instance is in running state
[2025-02-23T10:49:58.188+0000] {logging_mixin.py:190} INFO -  Previous state of the Task instance: queued
[2025-02-23T10:49:58.192+0000] {logging_mixin.py:190} INFO - Current task name:send_notification state:running start_date:2025-02-23 10:49:57.102757+00:00
[2025-02-23T10:49:58.194+0000] {logging_mixin.py:190} INFO - Dag name:idp and current dag run status:running
[2025-02-23T10:49:58.199+0000] {taskinstance.py:731} INFO - ::endgroup::
[2025-02-23T10:49:58.351+0000] {logging_mixin.py:190} INFO - Retrying... HTTPConnectionPool(host='localhost', port=4000): Max retries exceeded with url: /socket.io/?transport=polling&EIO=4&t=1740307798.263951 (Caused by NewConnectionError('<urllib3.connection.HTTPConnection object at 0xffff628cc0e0>: Failed to establish a new connection: [Errno 111] Connection refused'))
[2025-02-23T10:50:00.401+0000] {logging_mixin.py:190} INFO - Retrying... HTTPConnectionPool(host='localhost', port=4000): Max retries exceeded with url: /socket.io/?transport=polling&EIO=4&t=1740307800.3717449 (Caused by NewConnectionError('<urllib3.connection.HTTPConnection object at 0xffff62711910>: Failed to establish a new connection: [Errno 111] Connection refused'))
[2025-02-23T10:50:02.502+0000] {logging_mixin.py:190} INFO - Retrying... HTTPConnectionPool(host='localhost', port=4000): Max retries exceeded with url: /socket.io/?transport=polling&EIO=4&t=1740307802.4247544 (Caused by NewConnectionError('<urllib3.connection.HTTPConnection object at 0xffff62712300>: Failed to establish a new connection: [Errno 111] Connection refused'))
[2025-02-23T10:50:04.559+0000] {logging_mixin.py:190} INFO - Retrying... HTTPConnectionPool(host='localhost', port=4000): Max retries exceeded with url: /socket.io/?transport=polling&EIO=4&t=1740307804.5185995 (Caused by NewConnectionError('<urllib3.connection.HTTPConnection object at 0xffff628993a0>: Failed to establish a new connection: [Errno 111] Connection refused'))
[2025-02-23T10:50:06.641+0000] {logging_mixin.py:190} INFO - Retrying... HTTPConnectionPool(host='localhost', port=4000): Max retries exceeded with url: /socket.io/?transport=polling&EIO=4&t=1740307806.5913923 (Caused by NewConnectionError('<urllib3.connection.HTTPConnection object at 0xffff62712420>: Failed to establish a new connection: [Errno 111] Connection refused'))
[2025-02-23T10:50:08.685+0000] {taskinstance.py:3311} ERROR - Task failed with exception
Traceback (most recent call last):
  File "/home/airflow/.local/lib/python3.12/site-packages/airflow/models/taskinstance.py", line 767, in _execute_task
    result = _execute_callable(context=context, **execute_callable_kwargs)
             ^^^^^^^^^^^^^^^^^^^^^^^^^^^^^^^^^^^^^^^^^^^^^^^^^^^^^^^^^^^^^
  File "/home/airflow/.local/lib/python3.12/site-packages/airflow/models/taskinstance.py", line 733, in _execute_callable
    return ExecutionCallableRunner(
           ^^^^^^^^^^^^^^^^^^^^^^^^
  File "/home/airflow/.local/lib/python3.12/site-packages/airflow/utils/operator_helpers.py", line 252, in run
    return self.func(*args, **kwargs)
           ^^^^^^^^^^^^^^^^^^^^^^^^^^
  File "/home/airflow/.local/lib/python3.12/site-packages/airflow/models/baseoperator.py", line 422, in wrapper
    return func(self, *args, **kwargs)
           ^^^^^^^^^^^^^^^^^^^^^^^^^^^
  File "/home/airflow/.local/lib/python3.12/site-packages/airflow/operators/python.py", line 238, in execute
    return_value = self.execute_callable()
                   ^^^^^^^^^^^^^^^^^^^^^^^
  File "/home/airflow/.local/lib/python3.12/site-packages/airflow/operators/python.py", line 256, in execute_callable
    return runner.run(*self.op_args, **self.op_kwargs)
           ^^^^^^^^^^^^^^^^^^^^^^^^^^^^^^^^^^^^^^^^^^^
  File "/home/airflow/.local/lib/python3.12/site-packages/airflow/utils/operator_helpers.py", line 252, in run
    return self.func(*args, **kwargs)
           ^^^^^^^^^^^^^^^^^^^^^^^^^^
  File "/opt/airflow/dags/idp.py", line 144, in send_notification
    sio.emit('notification', {'message': 'Your virtual machine is being created now'})
  File "/home/airflow/.local/lib/python3.12/site-packages/socketio/client.py", line 219, in emit
    raise exceptions.BadNamespaceError(
socketio.exceptions.BadNamespaceError: / is not a connected namespace.
[2025-02-23T10:50:08.927+0000] {logging_mixin.py:190} INFO - Task instance in failure state
[2025-02-23T10:50:08.929+0000] {logging_mixin.py:190} INFO - Task start:2025-02-23 10:49:57.102757+00:00 end:2025-02-23 10:50:08.912223+00:00 duration:11.809466
[2025-02-23T10:50:08.934+0000] {logging_mixin.py:190} INFO - Task:<Task(PythonOperator): send_notification> dag:<DAG: idp> dagrun:<DagRun idp @ 2025-02-23 10:48:28.568919+00:00: manual__2025-02-23T10:48:28.568919+00:00, state:running, queued_at: 2025-02-23 10:48:28.894621+00:00. externally triggered: True>
[2025-02-23T10:50:08.935+0000] {logging_mixin.py:190} INFO - Failure caused by / is not a connected namespace.
[2025-02-23T10:50:08.939+0000] {taskinstance.py:1225} INFO - Marking task as UP_FOR_RETRY. dag_id=idp, task_id=send_notification, run_id=manual__2025-02-23T10:48:28.568919+00:00, execution_date=20250223T104828, start_date=20250223T104957, end_date=20250223T105008
[2025-02-23T10:50:09.108+0000] {taskinstance.py:340} INFO - ::group::Post task execution logs
[2025-02-23T10:50:09.112+0000] {standard_task_runner.py:124} ERROR - Failed to execute job 393 for task send_notification (/ is not a connected namespace.; 2450)
Traceback (most recent call last):
  File "/home/airflow/.local/lib/python3.12/site-packages/airflow/task/task_runner/standard_task_runner.py", line 117, in _start_by_fork
    ret = args.func(args, dag=self.dag)
          ^^^^^^^^^^^^^^^^^^^^^^^^^^^^^
  File "/home/airflow/.local/lib/python3.12/site-packages/airflow/cli/cli_config.py", line 49, in command
    return func(*args, **kwargs)
           ^^^^^^^^^^^^^^^^^^^^^
  File "/home/airflow/.local/lib/python3.12/site-packages/airflow/utils/cli.py", line 116, in wrapper
    return f(*args, **kwargs)
           ^^^^^^^^^^^^^^^^^^
  File "/home/airflow/.local/lib/python3.12/site-packages/airflow/cli/commands/task_command.py", line 483, in task_run
    task_return_code = _run_task_by_selected_method(args, _dag, ti)
                       ^^^^^^^^^^^^^^^^^^^^^^^^^^^^^^^^^^^^^^^^^^^^
  File "/home/airflow/.local/lib/python3.12/site-packages/airflow/cli/commands/task_command.py", line 256, in _run_task_by_selected_method
    return _run_raw_task(args, ti)
           ^^^^^^^^^^^^^^^^^^^^^^^
  File "/home/airflow/.local/lib/python3.12/site-packages/airflow/cli/commands/task_command.py", line 341, in _run_raw_task
    return ti._run_raw_task(
           ^^^^^^^^^^^^^^^^^
  File "/home/airflow/.local/lib/python3.12/site-packages/airflow/utils/session.py", line 97, in wrapper
    return func(*args, session=session, **kwargs)
           ^^^^^^^^^^^^^^^^^^^^^^^^^^^^^^^^^^^^^^
  File "/home/airflow/.local/lib/python3.12/site-packages/airflow/models/taskinstance.py", line 3005, in _run_raw_task
    return _run_raw_task(
           ^^^^^^^^^^^^^^
  File "/home/airflow/.local/lib/python3.12/site-packages/airflow/models/taskinstance.py", line 273, in _run_raw_task
    TaskInstance._execute_task_with_callbacks(
  File "/home/airflow/.local/lib/python3.12/site-packages/airflow/models/taskinstance.py", line 3159, in _execute_task_with_callbacks
    result = self._execute_task(context, task_orig)
             ^^^^^^^^^^^^^^^^^^^^^^^^^^^^^^^^^^^^^^
  File "/home/airflow/.local/lib/python3.12/site-packages/airflow/models/taskinstance.py", line 3183, in _execute_task
    return _execute_task(self, context, task_orig)
           ^^^^^^^^^^^^^^^^^^^^^^^^^^^^^^^^^^^^^^^
  File "/home/airflow/.local/lib/python3.12/site-packages/airflow/models/taskinstance.py", line 767, in _execute_task
    result = _execute_callable(context=context, **execute_callable_kwargs)
             ^^^^^^^^^^^^^^^^^^^^^^^^^^^^^^^^^^^^^^^^^^^^^^^^^^^^^^^^^^^^^
  File "/home/airflow/.local/lib/python3.12/site-packages/airflow/models/taskinstance.py", line 733, in _execute_callable
    return ExecutionCallableRunner(
           ^^^^^^^^^^^^^^^^^^^^^^^^
  File "/home/airflow/.local/lib/python3.12/site-packages/airflow/utils/operator_helpers.py", line 252, in run
    return self.func(*args, **kwargs)
           ^^^^^^^^^^^^^^^^^^^^^^^^^^
  File "/home/airflow/.local/lib/python3.12/site-packages/airflow/models/baseoperator.py", line 422, in wrapper
    return func(self, *args, **kwargs)
           ^^^^^^^^^^^^^^^^^^^^^^^^^^^
  File "/home/airflow/.local/lib/python3.12/site-packages/airflow/operators/python.py", line 238, in execute
    return_value = self.execute_callable()
                   ^^^^^^^^^^^^^^^^^^^^^^^
  File "/home/airflow/.local/lib/python3.12/site-packages/airflow/operators/python.py", line 256, in execute_callable
    return runner.run(*self.op_args, **self.op_kwargs)
           ^^^^^^^^^^^^^^^^^^^^^^^^^^^^^^^^^^^^^^^^^^^
  File "/home/airflow/.local/lib/python3.12/site-packages/airflow/utils/operator_helpers.py", line 252, in run
    return self.func(*args, **kwargs)
           ^^^^^^^^^^^^^^^^^^^^^^^^^^
  File "/opt/airflow/dags/idp.py", line 144, in send_notification
    sio.emit('notification', {'message': 'Your virtual machine is being created now'})
  File "/home/airflow/.local/lib/python3.12/site-packages/socketio/client.py", line 219, in emit
    raise exceptions.BadNamespaceError(
socketio.exceptions.BadNamespaceError: / is not a connected namespace.
[2025-02-23T10:50:09.186+0000] {local_task_job_runner.py:266} INFO - Task exited with return code 1
[2025-02-23T10:50:09.562+0000] {taskinstance.py:3895} INFO - 0 downstream tasks scheduled from follow-on schedule check
[2025-02-23T10:50:09.581+0000] {local_task_job_runner.py:245} INFO - ::endgroup::
