[2025-02-04T14:00:08.546+0000] {local_task_job_runner.py:123} INFO - ::group::Pre task execution logs
[2025-02-04T14:00:08.568+0000] {taskinstance.py:2613} INFO - Dependencies all met for dep_context=non-requeueable deps ti=<TaskInstance: idp_fetch_mongo.fetch_from_mongo manual__2025-02-04T13:59:06.567326+00:00 [queued]>
[2025-02-04T14:00:08.575+0000] {taskinstance.py:2613} INFO - Dependencies all met for dep_context=requeueable deps ti=<TaskInstance: idp_fetch_mongo.fetch_from_mongo manual__2025-02-04T13:59:06.567326+00:00 [queued]>
[2025-02-04T14:00:08.578+0000] {taskinstance.py:2866} INFO - Starting attempt 1 of 2
[2025-02-04T14:00:08.592+0000] {taskinstance.py:2889} INFO - Executing <Task(PythonOperator): fetch_from_mongo> on 2025-02-04 13:59:06.567326+00:00
[2025-02-04T14:00:08.619+0000] {standard_task_runner.py:104} INFO - Running: ['***', 'tasks', 'run', 'idp_fetch_mongo', 'fetch_from_mongo', 'manual__2025-02-04T13:59:06.567326+00:00', '--job-id', '190', '--raw', '--subdir', 'DAGS_FOLDER/idp.py', '--cfg-path', '/tmp/tmphw189oqv']
[2025-02-04T14:00:08.617+0000] {warnings.py:112} WARNING - /home/***/.local/lib/python3.12/site-packages/***/task/task_runner/standard_task_runner.py:70: DeprecationWarning: This process (pid=97) is multi-threaded, use of fork() may lead to deadlocks in the child.
  pid = os.fork()

[2025-02-04T14:00:08.622+0000] {standard_task_runner.py:105} INFO - Job 190: Subtask fetch_from_mongo
[2025-02-04T14:00:08.622+0000] {standard_task_runner.py:72} INFO - Started process 100 to run task
[2025-02-04T14:00:08.750+0000] {task_command.py:467} INFO - Running <TaskInstance: idp_fetch_mongo.fetch_from_mongo manual__2025-02-04T13:59:06.567326+00:00 [running]> on host 3aa1f743f988
[2025-02-04T14:00:08.861+0000] {taskinstance.py:3132} INFO - Exporting env vars: AIRFLOW_CTX_DAG_OWNER='***' AIRFLOW_CTX_DAG_ID='idp_fetch_mongo' AIRFLOW_CTX_TASK_ID='fetch_from_mongo' AIRFLOW_CTX_EXECUTION_DATE='2025-02-04T13:59:06.567326+00:00' AIRFLOW_CTX_TRY_NUMBER='1' AIRFLOW_CTX_DAG_RUN_ID='manual__2025-02-04T13:59:06.567326+00:00'
[2025-02-04T14:00:08.866+0000] {logging_mixin.py:190} INFO - Task instance is in running state
[2025-02-04T14:00:08.866+0000] {logging_mixin.py:190} INFO -  Previous state of the Task instance: queued
[2025-02-04T14:00:08.867+0000] {logging_mixin.py:190} INFO - Current task name:fetch_from_mongo state:running start_date:2025-02-04 14:00:08.568808+00:00
[2025-02-04T14:00:08.867+0000] {logging_mixin.py:190} INFO - Dag name:idp_fetch_mongo and current dag run status:running
[2025-02-04T14:00:08.867+0000] {taskinstance.py:731} INFO - ::endgroup::
[2025-02-04T14:00:08.871+0000] {logging_mixin.py:190} INFO - MONGODB_URI: None
[2025-02-04T14:00:08.872+0000] {taskinstance.py:3311} ERROR - Task failed with exception
Traceback (most recent call last):
  File "/opt/airflow/dags/idp.py", line 17, in fetch_from_mongo
    raise Exception("MONGODB_URI is not set")
Exception: MONGODB_URI is not set

During handling of the above exception, another exception occurred:

Traceback (most recent call last):
  File "/opt/airflow/dags/idp.py", line 39, in fetch_from_mongo
    raise Exception(f"The following error occurred: {str(e)}")
Exception: The following error occurred: MONGODB_URI is not set

During handling of the above exception, another exception occurred:

Traceback (most recent call last):
  File "/home/airflow/.local/lib/python3.12/site-packages/airflow/models/taskinstance.py", line 767, in _execute_task
    result = _execute_callable(context=context, **execute_callable_kwargs)
             ^^^^^^^^^^^^^^^^^^^^^^^^^^^^^^^^^^^^^^^^^^^^^^^^^^^^^^^^^^^^^
  File "/home/airflow/.local/lib/python3.12/site-packages/airflow/models/taskinstance.py", line 733, in _execute_callable
    return ExecutionCallableRunner(
           ^^^^^^^^^^^^^^^^^^^^^^^^
  File "/home/airflow/.local/lib/python3.12/site-packages/airflow/utils/operator_helpers.py", line 252, in run
    return self.func(*args, **kwargs)
           ^^^^^^^^^^^^^^^^^^^^^^^^^^
  File "/home/airflow/.local/lib/python3.12/site-packages/airflow/models/baseoperator.py", line 422, in wrapper
    return func(self, *args, **kwargs)
           ^^^^^^^^^^^^^^^^^^^^^^^^^^^
  File "/home/airflow/.local/lib/python3.12/site-packages/airflow/operators/python.py", line 238, in execute
    return_value = self.execute_callable()
                   ^^^^^^^^^^^^^^^^^^^^^^^
  File "/home/airflow/.local/lib/python3.12/site-packages/airflow/operators/python.py", line 256, in execute_callable
    return runner.run(*self.op_args, **self.op_kwargs)
           ^^^^^^^^^^^^^^^^^^^^^^^^^^^^^^^^^^^^^^^^^^^
  File "/home/airflow/.local/lib/python3.12/site-packages/airflow/utils/operator_helpers.py", line 252, in run
    return self.func(*args, **kwargs)
           ^^^^^^^^^^^^^^^^^^^^^^^^^^
  File "/opt/airflow/dags/idp.py", line 42, in fetch_from_mongo
    client.close()  # Close client only after fetching data
    ^^^^^^
UnboundLocalError: cannot access local variable 'client' where it is not associated with a value
[2025-02-04T14:00:08.909+0000] {logging_mixin.py:190} INFO - Task instance in failure state
[2025-02-04T14:00:08.910+0000] {logging_mixin.py:190} INFO - Task start:2025-02-04 14:00:08.568808+00:00 end:2025-02-04 14:00:08.907476+00:00 duration:0.338668
[2025-02-04T14:00:08.911+0000] {logging_mixin.py:190} INFO - Task:<Task(PythonOperator): fetch_from_mongo> dag:<DAG: idp_fetch_mongo> dagrun:<DagRun idp_fetch_mongo @ 2025-02-04 13:59:06.567326+00:00: manual__2025-02-04T13:59:06.567326+00:00, state:running, queued_at: 2025-02-04 13:59:06.588182+00:00. externally triggered: True>
[2025-02-04T14:00:08.945+0000] {logging_mixin.py:190} INFO - Failure caused by cannot access local variable 'client' where it is not associated with a value
[2025-02-04T14:00:08.954+0000] {taskinstance.py:1225} INFO - Marking task as UP_FOR_RETRY. dag_id=idp_fetch_mongo, task_id=fetch_from_mongo, run_id=manual__2025-02-04T13:59:06.567326+00:00, execution_date=20250204T135906, start_date=20250204T140008, end_date=20250204T140008
[2025-02-04T14:00:08.993+0000] {taskinstance.py:340} INFO - ::group::Post task execution logs
[2025-02-04T14:00:08.996+0000] {standard_task_runner.py:124} ERROR - Failed to execute job 190 for task fetch_from_mongo (cannot access local variable 'client' where it is not associated with a value; 100)
Traceback (most recent call last):
  File "/opt/airflow/dags/idp.py", line 17, in fetch_from_mongo
    raise Exception("MONGODB_URI is not set")
Exception: MONGODB_URI is not set

During handling of the above exception, another exception occurred:

Traceback (most recent call last):
  File "/opt/airflow/dags/idp.py", line 39, in fetch_from_mongo
    raise Exception(f"The following error occurred: {str(e)}")
Exception: The following error occurred: MONGODB_URI is not set

During handling of the above exception, another exception occurred:

Traceback (most recent call last):
  File "/home/airflow/.local/lib/python3.12/site-packages/airflow/task/task_runner/standard_task_runner.py", line 117, in _start_by_fork
    ret = args.func(args, dag=self.dag)
          ^^^^^^^^^^^^^^^^^^^^^^^^^^^^^
  File "/home/airflow/.local/lib/python3.12/site-packages/airflow/cli/cli_config.py", line 49, in command
    return func(*args, **kwargs)
           ^^^^^^^^^^^^^^^^^^^^^
  File "/home/airflow/.local/lib/python3.12/site-packages/airflow/utils/cli.py", line 116, in wrapper
    return f(*args, **kwargs)
           ^^^^^^^^^^^^^^^^^^
  File "/home/airflow/.local/lib/python3.12/site-packages/airflow/cli/commands/task_command.py", line 483, in task_run
    task_return_code = _run_task_by_selected_method(args, _dag, ti)
                       ^^^^^^^^^^^^^^^^^^^^^^^^^^^^^^^^^^^^^^^^^^^^
  File "/home/airflow/.local/lib/python3.12/site-packages/airflow/cli/commands/task_command.py", line 256, in _run_task_by_selected_method
    return _run_raw_task(args, ti)
           ^^^^^^^^^^^^^^^^^^^^^^^
  File "/home/airflow/.local/lib/python3.12/site-packages/airflow/cli/commands/task_command.py", line 341, in _run_raw_task
    return ti._run_raw_task(
           ^^^^^^^^^^^^^^^^^
  File "/home/airflow/.local/lib/python3.12/site-packages/airflow/utils/session.py", line 97, in wrapper
    return func(*args, session=session, **kwargs)
           ^^^^^^^^^^^^^^^^^^^^^^^^^^^^^^^^^^^^^^
  File "/home/airflow/.local/lib/python3.12/site-packages/airflow/models/taskinstance.py", line 3005, in _run_raw_task
    return _run_raw_task(
           ^^^^^^^^^^^^^^
  File "/home/airflow/.local/lib/python3.12/site-packages/airflow/models/taskinstance.py", line 273, in _run_raw_task
    TaskInstance._execute_task_with_callbacks(
  File "/home/airflow/.local/lib/python3.12/site-packages/airflow/models/taskinstance.py", line 3159, in _execute_task_with_callbacks
    result = self._execute_task(context, task_orig)
             ^^^^^^^^^^^^^^^^^^^^^^^^^^^^^^^^^^^^^^
  File "/home/airflow/.local/lib/python3.12/site-packages/airflow/models/taskinstance.py", line 3183, in _execute_task
    return _execute_task(self, context, task_orig)
           ^^^^^^^^^^^^^^^^^^^^^^^^^^^^^^^^^^^^^^^
  File "/home/airflow/.local/lib/python3.12/site-packages/airflow/models/taskinstance.py", line 767, in _execute_task
    result = _execute_callable(context=context, **execute_callable_kwargs)
             ^^^^^^^^^^^^^^^^^^^^^^^^^^^^^^^^^^^^^^^^^^^^^^^^^^^^^^^^^^^^^
  File "/home/airflow/.local/lib/python3.12/site-packages/airflow/models/taskinstance.py", line 733, in _execute_callable
    return ExecutionCallableRunner(
           ^^^^^^^^^^^^^^^^^^^^^^^^
  File "/home/airflow/.local/lib/python3.12/site-packages/airflow/utils/operator_helpers.py", line 252, in run
    return self.func(*args, **kwargs)
           ^^^^^^^^^^^^^^^^^^^^^^^^^^
  File "/home/airflow/.local/lib/python3.12/site-packages/airflow/models/baseoperator.py", line 422, in wrapper
    return func(self, *args, **kwargs)
           ^^^^^^^^^^^^^^^^^^^^^^^^^^^
  File "/home/airflow/.local/lib/python3.12/site-packages/airflow/operators/python.py", line 238, in execute
    return_value = self.execute_callable()
                   ^^^^^^^^^^^^^^^^^^^^^^^
  File "/home/airflow/.local/lib/python3.12/site-packages/airflow/operators/python.py", line 256, in execute_callable
    return runner.run(*self.op_args, **self.op_kwargs)
           ^^^^^^^^^^^^^^^^^^^^^^^^^^^^^^^^^^^^^^^^^^^
  File "/home/airflow/.local/lib/python3.12/site-packages/airflow/utils/operator_helpers.py", line 252, in run
    return self.func(*args, **kwargs)
           ^^^^^^^^^^^^^^^^^^^^^^^^^^
  File "/opt/airflow/dags/idp.py", line 42, in fetch_from_mongo
    client.close()  # Close client only after fetching data
    ^^^^^^
UnboundLocalError: cannot access local variable 'client' where it is not associated with a value
[2025-02-04T14:00:09.026+0000] {local_task_job_runner.py:266} INFO - Task exited with return code 1
[2025-02-04T14:00:09.046+0000] {taskinstance.py:3895} INFO - 0 downstream tasks scheduled from follow-on schedule check
[2025-02-04T14:00:09.048+0000] {local_task_job_runner.py:245} INFO - ::endgroup::
