[2025-02-22T04:57:19.568+0000] {local_task_job_runner.py:123} INFO - ::group::Pre task execution logs
[2025-02-22T04:57:19.577+0000] {taskinstance.py:2613} INFO - Dependencies all met for dep_context=non-requeueable deps ti=<TaskInstance: idp.rabbitmq_consumer manual__2025-02-22T04:57:18.035764+00:00 [queued]>
[2025-02-22T04:57:19.581+0000] {taskinstance.py:2613} INFO - Dependencies all met for dep_context=requeueable deps ti=<TaskInstance: idp.rabbitmq_consumer manual__2025-02-22T04:57:18.035764+00:00 [queued]>
[2025-02-22T04:57:19.582+0000] {taskinstance.py:2866} INFO - Starting attempt 1 of 2
[2025-02-22T04:57:19.590+0000] {taskinstance.py:2889} INFO - Executing <Task(PythonOperator): rabbitmq_consumer> on 2025-02-22 04:57:18.035764+00:00
[2025-02-22T04:57:19.595+0000] {warnings.py:112} WARNING - /home/***/.local/lib/python3.12/site-packages/***/task/task_runner/standard_task_runner.py:70: DeprecationWarning: This process (pid=144) is multi-threaded, use of fork() may lead to deadlocks in the child.
  pid = os.fork()

[2025-02-22T04:57:19.597+0000] {standard_task_runner.py:72} INFO - Started process 145 to run task
[2025-02-22T04:57:19.598+0000] {standard_task_runner.py:104} INFO - Running: ['***', 'tasks', 'run', 'idp', 'rabbitmq_consumer', 'manual__2025-02-22T04:57:18.035764+00:00', '--job-id', '363', '--raw', '--subdir', 'DAGS_FOLDER/idp.py', '--cfg-path', '/tmp/tmpo9cobcay']
[2025-02-22T04:57:19.599+0000] {standard_task_runner.py:105} INFO - Job 363: Subtask rabbitmq_consumer
[2025-02-22T04:57:19.633+0000] {task_command.py:467} INFO - Running <TaskInstance: idp.rabbitmq_consumer manual__2025-02-22T04:57:18.035764+00:00 [running]> on host 9d363d0f65d2
[2025-02-22T04:57:19.689+0000] {taskinstance.py:3132} INFO - Exporting env vars: AIRFLOW_CTX_DAG_OWNER='***' AIRFLOW_CTX_DAG_ID='idp' AIRFLOW_CTX_TASK_ID='rabbitmq_consumer' AIRFLOW_CTX_EXECUTION_DATE='2025-02-22T04:57:18.035764+00:00' AIRFLOW_CTX_TRY_NUMBER='1' AIRFLOW_CTX_DAG_RUN_ID='manual__2025-02-22T04:57:18.035764+00:00'
[2025-02-22T04:57:19.690+0000] {logging_mixin.py:190} INFO - Task instance is in running state
[2025-02-22T04:57:19.690+0000] {logging_mixin.py:190} INFO -  Previous state of the Task instance: queued
[2025-02-22T04:57:19.690+0000] {logging_mixin.py:190} INFO - Current task name:rabbitmq_consumer state:running start_date:2025-02-22 04:57:19.577685+00:00
[2025-02-22T04:57:19.691+0000] {logging_mixin.py:190} INFO - Dag name:idp and current dag run status:running
[2025-02-22T04:57:19.691+0000] {taskinstance.py:731} INFO - ::endgroup::
[2025-02-22T04:57:19.695+0000] {connection_workflow.py:179} INFO - Pika version 1.3.2 connecting to ('172.19.0.5', 5672)
[2025-02-22T04:57:19.696+0000] {io_services_utils.py:345} INFO - Socket connected: <socket.socket fd=93, family=2, type=1, proto=6, laddr=('172.19.0.8', 39902), raddr=('172.19.0.5', 5672)>
[2025-02-22T04:57:19.701+0000] {connection_workflow.py:428} INFO - Streaming transport linked up: (<pika.adapters.utils.io_services_utils._AsyncPlaintextTransport object at 0xffff84d8bf20>, _StreamingProtocolShim: <SelectConnection PROTOCOL transport=<pika.adapters.utils.io_services_utils._AsyncPlaintextTransport object at 0xffff84d8bf20> params=<ConnectionParameters host=rabbitmq port=5672 virtual_host=/ ssl=False>>).
[2025-02-22T04:57:19.706+0000] {connection_workflow.py:293} INFO - AMQPConnector - reporting success: <SelectConnection OPEN transport=<pika.adapters.utils.io_services_utils._AsyncPlaintextTransport object at 0xffff84d8bf20> params=<ConnectionParameters host=rabbitmq port=5672 virtual_host=/ ssl=False>>
[2025-02-22T04:57:19.706+0000] {connection_workflow.py:725} INFO - AMQPConnectionWorkflow - reporting success: <SelectConnection OPEN transport=<pika.adapters.utils.io_services_utils._AsyncPlaintextTransport object at 0xffff84d8bf20> params=<ConnectionParameters host=rabbitmq port=5672 virtual_host=/ ssl=False>>
[2025-02-22T04:57:19.707+0000] {blocking_connection.py:453} INFO - Connection workflow succeeded: <SelectConnection OPEN transport=<pika.adapters.utils.io_services_utils._AsyncPlaintextTransport object at 0xffff84d8bf20> params=<ConnectionParameters host=rabbitmq port=5672 virtual_host=/ ssl=False>>
[2025-02-22T04:57:19.707+0000] {blocking_connection.py:1264} INFO - Created channel=1
[2025-02-22T04:57:19.709+0000] {logging_mixin.py:190} INFO - Queue create-vm has 0 messages
[2025-02-22T04:57:19.710+0000] {logging_mixin.py:190} INFO - Listening for messages in queue: create-vm
[2025-02-22T05:03:43.910+0000] {job.py:229} INFO - Heartbeat recovered after 303.45 seconds
[2025-02-22T05:10:36.472+0000] {job.py:229} INFO - Heartbeat recovered after 387.04 seconds
[2025-02-22T05:51:42.658+0000] {job.py:229} INFO - Heartbeat recovered after 2440.74 seconds
[2025-02-22T05:52:30.498+0000] {job.py:229} INFO - Heartbeat recovered after 22.46 seconds
[2025-02-22T05:54:19.976+0000] {job.py:229} INFO - Heartbeat recovered after 28.73 seconds
[2025-02-22T05:56:14.777+0000] {io_services_utils.py:731} INFO - Aborting transport connection: state=1; <socket.socket fd=93, family=2, type=1, proto=6, laddr=('172.19.0.8', 39902)>
[2025-02-22T05:56:14.989+0000] {io_services_utils.py:904} INFO - _AsyncTransportBase._initate_abort(): Initiating abrupt asynchronous transport shutdown: state=1; error=None; <socket.socket fd=93, family=2, type=1, proto=6, laddr=('172.19.0.8', 39902)>
[2025-02-22T05:56:14.993+0000] {io_services_utils.py:869} INFO - Deactivating transport: state=1; <socket.socket fd=93, family=2, type=1, proto=6, laddr=('172.19.0.8', 39902)>
[2025-02-22T05:56:14.999+0000] {connection.py:2017} INFO - AMQP stack terminated, failed to connect, or aborted: opened=True, error-arg=None; pending-error=ConnectionClosedByBroker: (320) "CONNECTION_FORCED - broker forced connection closure with reason 'shutdown'"
[2025-02-22T05:56:15.005+0000] {connection.py:2086} INFO - Stack terminated due to ConnectionClosedByBroker: (320) "CONNECTION_FORCED - broker forced connection closure with reason 'shutdown'"
[2025-02-22T05:56:15.034+0000] {io_services_utils.py:882} INFO - Closing transport socket and unlinking: state=3; <socket.socket fd=93, family=2, type=1, proto=6, laddr=('172.19.0.8', 39902)>
[2025-02-22T05:56:15.036+0000] {blocking_connection.py:521} ERROR - Unexpected connection close detected: ConnectionClosedByBroker: (320) "CONNECTION_FORCED - broker forced connection closure with reason 'shutdown'"
[2025-02-22T05:56:15.039+0000] {logging_mixin.py:190} INFO - Error in listener: (320, "CONNECTION_FORCED - broker forced connection closure with reason 'shutdown'")
[2025-02-22T05:56:15.040+0000] {logging_mixin.py:190} INFO - Listener stopped.
[2025-02-22T05:56:15.042+0000] {python.py:240} INFO - Done. Returned value was: 
[2025-02-22T05:56:18.457+0000] {job.py:239} ERROR - Job heartbeat failed with error
Traceback (most recent call last):
  File "/home/airflow/.local/lib/python3.12/site-packages/sqlalchemy/engine/base.py", line 3371, in _wrap_pool_connect
    return fn()
           ^^^^
  File "/home/airflow/.local/lib/python3.12/site-packages/sqlalchemy/pool/base.py", line 327, in connect
    return _ConnectionFairy._checkout(self)
           ^^^^^^^^^^^^^^^^^^^^^^^^^^^^^^^^
  File "/home/airflow/.local/lib/python3.12/site-packages/sqlalchemy/pool/base.py", line 894, in _checkout
    fairy = _ConnectionRecord.checkout(pool)
            ^^^^^^^^^^^^^^^^^^^^^^^^^^^^^^^^
  File "/home/airflow/.local/lib/python3.12/site-packages/sqlalchemy/pool/base.py", line 493, in checkout
    rec = pool._do_get()
          ^^^^^^^^^^^^^^
  File "/home/airflow/.local/lib/python3.12/site-packages/sqlalchemy/pool/impl.py", line 256, in _do_get
    return self._create_connection()
           ^^^^^^^^^^^^^^^^^^^^^^^^^
  File "/home/airflow/.local/lib/python3.12/site-packages/sqlalchemy/pool/base.py", line 273, in _create_connection
    return _ConnectionRecord(self)
           ^^^^^^^^^^^^^^^^^^^^^^^
  File "/home/airflow/.local/lib/python3.12/site-packages/sqlalchemy/pool/base.py", line 388, in __init__
    self.__connect()
  File "/home/airflow/.local/lib/python3.12/site-packages/sqlalchemy/pool/base.py", line 690, in __connect
    with util.safe_reraise():
         ^^^^^^^^^^^^^^^^^^^
  File "/home/airflow/.local/lib/python3.12/site-packages/sqlalchemy/util/langhelpers.py", line 70, in __exit__
    compat.raise_(
  File "/home/airflow/.local/lib/python3.12/site-packages/sqlalchemy/util/compat.py", line 211, in raise_
    raise exception
  File "/home/airflow/.local/lib/python3.12/site-packages/sqlalchemy/pool/base.py", line 686, in __connect
    self.dbapi_connection = connection = pool._invoke_creator(self)
                                         ^^^^^^^^^^^^^^^^^^^^^^^^^^
  File "/home/airflow/.local/lib/python3.12/site-packages/sqlalchemy/engine/create.py", line 574, in connect
    return dialect.connect(*cargs, **cparams)
           ^^^^^^^^^^^^^^^^^^^^^^^^^^^^^^^^^^
  File "/home/airflow/.local/lib/python3.12/site-packages/sqlalchemy/engine/default.py", line 598, in connect
    return self.dbapi.connect(*cargs, **cparams)
           ^^^^^^^^^^^^^^^^^^^^^^^^^^^^^^^^^^^^^
  File "/home/airflow/.local/lib/python3.12/site-packages/psycopg2/__init__.py", line 122, in connect
    conn = _connect(dsn, connection_factory=connection_factory, **kwasync)
           ^^^^^^^^^^^^^^^^^^^^^^^^^^^^^^^^^^^^^^^^^^^^^^^^^^^^^^^^^^^^^^^
psycopg2.OperationalError: could not translate host name "postgres" to address: Name or service not known


The above exception was the direct cause of the following exception:

Traceback (most recent call last):
  File "/home/airflow/.local/lib/python3.12/site-packages/airflow/jobs/job.py", line 207, in heartbeat
    self._merge_from(Job._fetch_from_db(self, session))
                     ^^^^^^^^^^^^^^^^^^^^^^^^^^^^^^^^^
  File "/home/airflow/.local/lib/python3.12/site-packages/airflow/api_internal/internal_api_call.py", line 166, in wrapper
    return func(*args, **kwargs)
           ^^^^^^^^^^^^^^^^^^^^^
  File "/home/airflow/.local/lib/python3.12/site-packages/airflow/utils/session.py", line 94, in wrapper
    return func(*args, **kwargs)
           ^^^^^^^^^^^^^^^^^^^^^
  File "/home/airflow/.local/lib/python3.12/site-packages/airflow/utils/retries.py", line 93, in wrapped_function
    for attempt in run_with_db_retries(max_retries=retries, logger=logger, **retry_kwargs):
                   ^^^^^^^^^^^^^^^^^^^^^^^^^^^^^^^^^^^^^^^^^^^^^^^^^^^^^^^^^^^^^^^^^^^^^^^
  File "/home/airflow/.local/lib/python3.12/site-packages/tenacity/__init__.py", line 443, in __iter__
    do = self.iter(retry_state=retry_state)
         ^^^^^^^^^^^^^^^^^^^^^^^^^^^^^^^^^^
  File "/home/airflow/.local/lib/python3.12/site-packages/tenacity/__init__.py", line 376, in iter
    result = action(retry_state)
             ^^^^^^^^^^^^^^^^^^^
  File "/home/airflow/.local/lib/python3.12/site-packages/tenacity/__init__.py", line 418, in exc_check
    raise retry_exc.reraise()
          ^^^^^^^^^^^^^^^^^^^
  File "/home/airflow/.local/lib/python3.12/site-packages/tenacity/__init__.py", line 185, in reraise
    raise self.last_attempt.result()
          ^^^^^^^^^^^^^^^^^^^^^^^^^^
  File "/usr/local/lib/python3.12/concurrent/futures/_base.py", line 449, in result
    return self.__get_result()
           ^^^^^^^^^^^^^^^^^^^
  File "/usr/local/lib/python3.12/concurrent/futures/_base.py", line 401, in __get_result
    raise self._exception
  File "/home/airflow/.local/lib/python3.12/site-packages/airflow/utils/retries.py", line 102, in wrapped_function
    return func(*args, **kwargs)
           ^^^^^^^^^^^^^^^^^^^^^
  File "/home/airflow/.local/lib/python3.12/site-packages/airflow/jobs/job.py", line 335, in _fetch_from_db
    session.merge(job)
  File "/home/airflow/.local/lib/python3.12/site-packages/sqlalchemy/orm/session.py", line 3056, in merge
    return self._merge(
           ^^^^^^^^^^^^
  File "/home/airflow/.local/lib/python3.12/site-packages/sqlalchemy/orm/session.py", line 3136, in _merge
    merged = self.get(
             ^^^^^^^^^
  File "/home/airflow/.local/lib/python3.12/site-packages/sqlalchemy/orm/session.py", line 2853, in get
    return self._get_impl(
           ^^^^^^^^^^^^^^^
  File "/home/airflow/.local/lib/python3.12/site-packages/sqlalchemy/orm/session.py", line 2975, in _get_impl
    return db_load_fn(
           ^^^^^^^^^^^
  File "/home/airflow/.local/lib/python3.12/site-packages/sqlalchemy/orm/loading.py", line 530, in load_on_pk_identity
    session.execute(
  File "/home/airflow/.local/lib/python3.12/site-packages/sqlalchemy/orm/session.py", line 1716, in execute
    conn = self._connection_for_bind(bind)
           ^^^^^^^^^^^^^^^^^^^^^^^^^^^^^^^
  File "/home/airflow/.local/lib/python3.12/site-packages/sqlalchemy/orm/session.py", line 1555, in _connection_for_bind
    return self._transaction._connection_for_bind(
           ^^^^^^^^^^^^^^^^^^^^^^^^^^^^^^^^^^^^^^^
  File "/home/airflow/.local/lib/python3.12/site-packages/sqlalchemy/orm/session.py", line 750, in _connection_for_bind
    conn = bind.connect()
           ^^^^^^^^^^^^^^
  File "/home/airflow/.local/lib/python3.12/site-packages/sqlalchemy/future/engine.py", line 412, in connect
    return super(Engine, self).connect()
           ^^^^^^^^^^^^^^^^^^^^^^^^^^^^^
  File "/home/airflow/.local/lib/python3.12/site-packages/sqlalchemy/engine/base.py", line 3325, in connect
    return self._connection_cls(self, close_with_result=close_with_result)
           ^^^^^^^^^^^^^^^^^^^^^^^^^^^^^^^^^^^^^^^^^^^^^^^^^^^^^^^^^^^^^^^
  File "/home/airflow/.local/lib/python3.12/site-packages/sqlalchemy/engine/base.py", line 96, in __init__
    else engine.raw_connection()
         ^^^^^^^^^^^^^^^^^^^^^^^
  File "/home/airflow/.local/lib/python3.12/site-packages/sqlalchemy/engine/base.py", line 3404, in raw_connection
    return self._wrap_pool_connect(self.pool.connect, _connection)
           ^^^^^^^^^^^^^^^^^^^^^^^^^^^^^^^^^^^^^^^^^^^^^^^^^^^^^^^
  File "/home/airflow/.local/lib/python3.12/site-packages/sqlalchemy/engine/base.py", line 3374, in _wrap_pool_connect
    Connection._handle_dbapi_exception_noconnection(
  File "/home/airflow/.local/lib/python3.12/site-packages/sqlalchemy/engine/base.py", line 2208, in _handle_dbapi_exception_noconnection
    util.raise_(
  File "/home/airflow/.local/lib/python3.12/site-packages/sqlalchemy/util/compat.py", line 211, in raise_
    raise exception
  File "/home/airflow/.local/lib/python3.12/site-packages/sqlalchemy/engine/base.py", line 3371, in _wrap_pool_connect
    return fn()
           ^^^^
  File "/home/airflow/.local/lib/python3.12/site-packages/sqlalchemy/pool/base.py", line 327, in connect
    return _ConnectionFairy._checkout(self)
           ^^^^^^^^^^^^^^^^^^^^^^^^^^^^^^^^
  File "/home/airflow/.local/lib/python3.12/site-packages/sqlalchemy/pool/base.py", line 894, in _checkout
    fairy = _ConnectionRecord.checkout(pool)
            ^^^^^^^^^^^^^^^^^^^^^^^^^^^^^^^^
  File "/home/airflow/.local/lib/python3.12/site-packages/sqlalchemy/pool/base.py", line 493, in checkout
    rec = pool._do_get()
          ^^^^^^^^^^^^^^
  File "/home/airflow/.local/lib/python3.12/site-packages/sqlalchemy/pool/impl.py", line 256, in _do_get
    return self._create_connection()
           ^^^^^^^^^^^^^^^^^^^^^^^^^
  File "/home/airflow/.local/lib/python3.12/site-packages/sqlalchemy/pool/base.py", line 273, in _create_connection
    return _ConnectionRecord(self)
           ^^^^^^^^^^^^^^^^^^^^^^^
  File "/home/airflow/.local/lib/python3.12/site-packages/sqlalchemy/pool/base.py", line 388, in __init__
    self.__connect()
  File "/home/airflow/.local/lib/python3.12/site-packages/sqlalchemy/pool/base.py", line 690, in __connect
    with util.safe_reraise():
         ^^^^^^^^^^^^^^^^^^^
  File "/home/airflow/.local/lib/python3.12/site-packages/sqlalchemy/util/langhelpers.py", line 70, in __exit__
    compat.raise_(
  File "/home/airflow/.local/lib/python3.12/site-packages/sqlalchemy/util/compat.py", line 211, in raise_
    raise exception
  File "/home/airflow/.local/lib/python3.12/site-packages/sqlalchemy/pool/base.py", line 686, in __connect
    self.dbapi_connection = connection = pool._invoke_creator(self)
                                         ^^^^^^^^^^^^^^^^^^^^^^^^^^
  File "/home/airflow/.local/lib/python3.12/site-packages/sqlalchemy/engine/create.py", line 574, in connect
    return dialect.connect(*cargs, **cparams)
           ^^^^^^^^^^^^^^^^^^^^^^^^^^^^^^^^^^
  File "/home/airflow/.local/lib/python3.12/site-packages/sqlalchemy/engine/default.py", line 598, in connect
    return self.dbapi.connect(*cargs, **cparams)
           ^^^^^^^^^^^^^^^^^^^^^^^^^^^^^^^^^^^^^
  File "/home/airflow/.local/lib/python3.12/site-packages/psycopg2/__init__.py", line 122, in connect
    conn = _connect(dsn, connection_factory=connection_factory, **kwasync)
           ^^^^^^^^^^^^^^^^^^^^^^^^^^^^^^^^^^^^^^^^^^^^^^^^^^^^^^^^^^^^^^^
sqlalchemy.exc.OperationalError: (psycopg2.OperationalError) could not translate host name "postgres" to address: Name or service not known

(Background on this error at: https://sqlalche.me/e/14/e3q8)
[2025-02-22T05:56:18.500+0000] {job.py:245} ERROR - Job heartbeat failed with error. Scheduler may go into unhealthy state
[2025-02-22T05:56:24.268+0000] {job.py:254} ERROR - Job heartbeat failed with error. Scheduler is in unhealthy state
[2025-02-23T07:27:58.597+0000] {local_task_job_runner.py:123} INFO - ::group::Pre task execution logs
[2025-02-23T07:27:58.611+0000] {taskinstance.py:2603} INFO - Dependencies not met for <TaskInstance: idp.rabbitmq_consumer manual__2025-02-22T04:57:18.035764+00:00 [running]>, dependency 'Task Instance State' FAILED: Task is in the 'running' state.
[2025-02-23T07:27:58.613+0000] {taskinstance.py:2603} INFO - Dependencies not met for <TaskInstance: idp.rabbitmq_consumer manual__2025-02-22T04:57:18.035764+00:00 [running]>, dependency 'Task Instance Not Running' FAILED: Task is in the running state
[2025-02-23T07:27:58.623+0000] {local_task_job_runner.py:166} INFO - Task is not able to be run
