[2025-02-23T07:58:05.030+0000] {local_task_job_runner.py:123} INFO - ::group::Pre task execution logs
[2025-02-23T07:58:05.042+0000] {taskinstance.py:2613} INFO - Dependencies all met for dep_context=non-requeueable deps ti=<TaskInstance: idp.fetch_from_mongo manual__2025-02-23T07:52:57.089685+00:00 [queued]>
[2025-02-23T07:58:05.049+0000] {taskinstance.py:2613} INFO - Dependencies all met for dep_context=requeueable deps ti=<TaskInstance: idp.fetch_from_mongo manual__2025-02-23T07:52:57.089685+00:00 [queued]>
[2025-02-23T07:58:05.050+0000] {taskinstance.py:2866} INFO - Starting attempt 2 of 2
[2025-02-23T07:58:05.065+0000] {taskinstance.py:2889} INFO - Executing <Task(PythonOperator): fetch_from_mongo> on 2025-02-23 07:52:57.089685+00:00
[2025-02-23T07:58:05.071+0000] {warnings.py:112} WARNING - /home/***/.local/lib/python3.12/site-packages/***/task/task_runner/standard_task_runner.py:70: DeprecationWarning: This process (pid=525) is multi-threaded, use of fork() may lead to deadlocks in the child.
  pid = os.fork()

[2025-02-23T07:58:05.072+0000] {standard_task_runner.py:72} INFO - Started process 526 to run task
[2025-02-23T07:58:05.072+0000] {standard_task_runner.py:104} INFO - Running: ['***', 'tasks', 'run', 'idp', 'fetch_from_mongo', 'manual__2025-02-23T07:52:57.089685+00:00', '--job-id', '376', '--raw', '--subdir', 'DAGS_FOLDER/idp.py', '--cfg-path', '/tmp/tmpp2i3m2k3']
[2025-02-23T07:58:05.073+0000] {standard_task_runner.py:105} INFO - Job 376: Subtask fetch_from_mongo
[2025-02-23T07:58:05.109+0000] {task_command.py:467} INFO - Running <TaskInstance: idp.fetch_from_mongo manual__2025-02-23T07:52:57.089685+00:00 [running]> on host 9d363d0f65d2
[2025-02-23T07:58:05.173+0000] {taskinstance.py:3132} INFO - Exporting env vars: AIRFLOW_CTX_DAG_OWNER='***' AIRFLOW_CTX_DAG_ID='idp' AIRFLOW_CTX_TASK_ID='fetch_from_mongo' AIRFLOW_CTX_EXECUTION_DATE='2025-02-23T07:52:57.089685+00:00' AIRFLOW_CTX_TRY_NUMBER='2' AIRFLOW_CTX_DAG_RUN_ID='manual__2025-02-23T07:52:57.089685+00:00'
[2025-02-23T07:58:05.174+0000] {logging_mixin.py:190} INFO - Task instance is in running state
[2025-02-23T07:58:05.175+0000] {logging_mixin.py:190} INFO -  Previous state of the Task instance: queued
[2025-02-23T07:58:05.175+0000] {logging_mixin.py:190} INFO - Current task name:fetch_from_mongo state:running start_date:2025-02-23 07:58:05.043332+00:00
[2025-02-23T07:58:05.175+0000] {logging_mixin.py:190} INFO - Dag name:idp and current dag run status:running
[2025-02-23T07:58:05.175+0000] {taskinstance.py:731} INFO - ::endgroup::
[2025-02-23T07:58:05.176+0000] {logging_mixin.py:190} INFO - Received message from XCom: 675266f7b8c017a58d30feaf
[2025-02-23T07:58:05.689+0000] {logging_mixin.py:190} INFO - Fetched data: [{'_id': ObjectId('6753b9cf35a9b131c31aa825'), 'userid': '12345', 'vmname': 'vm-testing', 'vmsize': 'Standard_A1_v2', 'region': 'East Asia', 'os': 'Ubuntu', 'type': 'Virtual Machine', 'username': 'admin-orchestronic1', 'password': 'SecureP@ss123', 'allocationip': 'Static', 'projectid': '675266f7b8c017a58d30feaf', '__v': 0}, {'_id': ObjectId('67582f17d6f4134db9805eaa'), 'userid': '12345', 'vmname': 'vm-development', 'vmsize': 'Standard_A1_v2', 'region': 'East Asia', 'os': 'Ubuntu', 'type': 'Virtual Machine', 'username': 'admin-orchestronic2', 'password': 'SecureP@ss123', 'allocationip': 'Static', 'projectid': '675266f7b8c017a58d30feaf', '__v': 0}]
[2025-02-23T07:58:05.738+0000] {taskinstance.py:3311} ERROR - Task failed with exception
Traceback (most recent call last):
  File "/opt/airflow/dags/idp.py", line 134, in fetch_from_mongo
    sio.connect('http://localhost:4000')
  File "/home/airflow/.local/lib/python3.12/site-packages/socketio/client.py", line 159, in connect
    raise exceptions.ConnectionError(exc.args[0]) from None
socketio.exceptions.ConnectionError: HTTPConnectionPool(host='localhost', port=4000): Max retries exceeded with url: /socket.io/?transport=polling&EIO=4&t=1740297485.6925874 (Caused by NewConnectionError('<urllib3.connection.HTTPConnection object at 0xffff628e8410>: Failed to establish a new connection: [Errno 111] Connection refused'))

During handling of the above exception, another exception occurred:

Traceback (most recent call last):
  File "/home/airflow/.local/lib/python3.12/site-packages/airflow/models/taskinstance.py", line 767, in _execute_task
    result = _execute_callable(context=context, **execute_callable_kwargs)
             ^^^^^^^^^^^^^^^^^^^^^^^^^^^^^^^^^^^^^^^^^^^^^^^^^^^^^^^^^^^^^
  File "/home/airflow/.local/lib/python3.12/site-packages/airflow/models/taskinstance.py", line 733, in _execute_callable
    return ExecutionCallableRunner(
           ^^^^^^^^^^^^^^^^^^^^^^^^
  File "/home/airflow/.local/lib/python3.12/site-packages/airflow/utils/operator_helpers.py", line 252, in run
    return self.func(*args, **kwargs)
           ^^^^^^^^^^^^^^^^^^^^^^^^^^
  File "/home/airflow/.local/lib/python3.12/site-packages/airflow/models/baseoperator.py", line 422, in wrapper
    return func(self, *args, **kwargs)
           ^^^^^^^^^^^^^^^^^^^^^^^^^^^
  File "/home/airflow/.local/lib/python3.12/site-packages/airflow/operators/python.py", line 238, in execute
    return_value = self.execute_callable()
                   ^^^^^^^^^^^^^^^^^^^^^^^
  File "/home/airflow/.local/lib/python3.12/site-packages/airflow/operators/python.py", line 256, in execute_callable
    return runner.run(*self.op_args, **self.op_kwargs)
           ^^^^^^^^^^^^^^^^^^^^^^^^^^^^^^^^^^^^^^^^^^^
  File "/home/airflow/.local/lib/python3.12/site-packages/airflow/utils/operator_helpers.py", line 252, in run
    return self.func(*args, **kwargs)
           ^^^^^^^^^^^^^^^^^^^^^^^^^^
  File "/opt/airflow/dags/idp.py", line 139, in fetch_from_mongo
    raise Exception(f"The following error occurred: {str(e)}")
Exception: The following error occurred: HTTPConnectionPool(host='localhost', port=4000): Max retries exceeded with url: /socket.io/?transport=polling&EIO=4&t=1740297485.6925874 (Caused by NewConnectionError('<urllib3.connection.HTTPConnection object at 0xffff628e8410>: Failed to establish a new connection: [Errno 111] Connection refused'))
[2025-02-23T07:58:05.748+0000] {logging_mixin.py:190} INFO - Task instance in failure state
[2025-02-23T07:58:05.750+0000] {logging_mixin.py:190} INFO - Task start:2025-02-23 07:58:05.043332+00:00 end:2025-02-23 07:58:05.747875+00:00 duration:0.704543
[2025-02-23T07:58:05.751+0000] {logging_mixin.py:190} INFO - Task:<Task(PythonOperator): fetch_from_mongo> dag:<DAG: idp> dagrun:<DagRun idp @ 2025-02-23 07:52:57.089685+00:00: manual__2025-02-23T07:52:57.089685+00:00, state:running, queued_at: 2025-02-23 07:52:57.099053+00:00. externally triggered: True>
[2025-02-23T07:58:05.751+0000] {logging_mixin.py:190} INFO - Failure caused by The following error occurred: HTTPConnectionPool(host='localhost', port=4000): Max retries exceeded with url: /socket.io/?transport=polling&EIO=4&t=1740297485.6925874 (Caused by NewConnectionError('<urllib3.connection.HTTPConnection object at 0xffff628e8410>: Failed to establish a new connection: [Errno 111] Connection refused'))
[2025-02-23T07:58:05.751+0000] {taskinstance.py:1225} INFO - Marking task as FAILED. dag_id=idp, task_id=fetch_from_mongo, run_id=manual__2025-02-23T07:52:57.089685+00:00, execution_date=20250223T075257, start_date=20250223T075805, end_date=20250223T075805
[2025-02-23T07:58:05.764+0000] {taskinstance.py:340} INFO - ::group::Post task execution logs
[2025-02-23T07:58:05.765+0000] {standard_task_runner.py:124} ERROR - Failed to execute job 376 for task fetch_from_mongo (The following error occurred: HTTPConnectionPool(host='localhost', port=4000): Max retries exceeded with url: /socket.io/?transport=polling&EIO=4&t=1740297485.6925874 (Caused by NewConnectionError('<urllib3.connection.HTTPConnection object at 0xffff628e8410>: Failed to establish a new connection: [Errno 111] Connection refused')); 526)
Traceback (most recent call last):
  File "/opt/airflow/dags/idp.py", line 134, in fetch_from_mongo
    sio.connect('http://localhost:4000')
  File "/home/airflow/.local/lib/python3.12/site-packages/socketio/client.py", line 159, in connect
    raise exceptions.ConnectionError(exc.args[0]) from None
socketio.exceptions.ConnectionError: HTTPConnectionPool(host='localhost', port=4000): Max retries exceeded with url: /socket.io/?transport=polling&EIO=4&t=1740297485.6925874 (Caused by NewConnectionError('<urllib3.connection.HTTPConnection object at 0xffff628e8410>: Failed to establish a new connection: [Errno 111] Connection refused'))

During handling of the above exception, another exception occurred:

Traceback (most recent call last):
  File "/home/airflow/.local/lib/python3.12/site-packages/airflow/task/task_runner/standard_task_runner.py", line 117, in _start_by_fork
    ret = args.func(args, dag=self.dag)
          ^^^^^^^^^^^^^^^^^^^^^^^^^^^^^
  File "/home/airflow/.local/lib/python3.12/site-packages/airflow/cli/cli_config.py", line 49, in command
    return func(*args, **kwargs)
           ^^^^^^^^^^^^^^^^^^^^^
  File "/home/airflow/.local/lib/python3.12/site-packages/airflow/utils/cli.py", line 116, in wrapper
    return f(*args, **kwargs)
           ^^^^^^^^^^^^^^^^^^
  File "/home/airflow/.local/lib/python3.12/site-packages/airflow/cli/commands/task_command.py", line 483, in task_run
    task_return_code = _run_task_by_selected_method(args, _dag, ti)
                       ^^^^^^^^^^^^^^^^^^^^^^^^^^^^^^^^^^^^^^^^^^^^
  File "/home/airflow/.local/lib/python3.12/site-packages/airflow/cli/commands/task_command.py", line 256, in _run_task_by_selected_method
    return _run_raw_task(args, ti)
           ^^^^^^^^^^^^^^^^^^^^^^^
  File "/home/airflow/.local/lib/python3.12/site-packages/airflow/cli/commands/task_command.py", line 341, in _run_raw_task
    return ti._run_raw_task(
           ^^^^^^^^^^^^^^^^^
  File "/home/airflow/.local/lib/python3.12/site-packages/airflow/utils/session.py", line 97, in wrapper
    return func(*args, session=session, **kwargs)
           ^^^^^^^^^^^^^^^^^^^^^^^^^^^^^^^^^^^^^^
  File "/home/airflow/.local/lib/python3.12/site-packages/airflow/models/taskinstance.py", line 3005, in _run_raw_task
    return _run_raw_task(
           ^^^^^^^^^^^^^^
  File "/home/airflow/.local/lib/python3.12/site-packages/airflow/models/taskinstance.py", line 273, in _run_raw_task
    TaskInstance._execute_task_with_callbacks(
  File "/home/airflow/.local/lib/python3.12/site-packages/airflow/models/taskinstance.py", line 3159, in _execute_task_with_callbacks
    result = self._execute_task(context, task_orig)
             ^^^^^^^^^^^^^^^^^^^^^^^^^^^^^^^^^^^^^^
  File "/home/airflow/.local/lib/python3.12/site-packages/airflow/models/taskinstance.py", line 3183, in _execute_task
    return _execute_task(self, context, task_orig)
           ^^^^^^^^^^^^^^^^^^^^^^^^^^^^^^^^^^^^^^^
  File "/home/airflow/.local/lib/python3.12/site-packages/airflow/models/taskinstance.py", line 767, in _execute_task
    result = _execute_callable(context=context, **execute_callable_kwargs)
             ^^^^^^^^^^^^^^^^^^^^^^^^^^^^^^^^^^^^^^^^^^^^^^^^^^^^^^^^^^^^^
  File "/home/airflow/.local/lib/python3.12/site-packages/airflow/models/taskinstance.py", line 733, in _execute_callable
    return ExecutionCallableRunner(
           ^^^^^^^^^^^^^^^^^^^^^^^^
  File "/home/airflow/.local/lib/python3.12/site-packages/airflow/utils/operator_helpers.py", line 252, in run
    return self.func(*args, **kwargs)
           ^^^^^^^^^^^^^^^^^^^^^^^^^^
  File "/home/airflow/.local/lib/python3.12/site-packages/airflow/models/baseoperator.py", line 422, in wrapper
    return func(self, *args, **kwargs)
           ^^^^^^^^^^^^^^^^^^^^^^^^^^^
  File "/home/airflow/.local/lib/python3.12/site-packages/airflow/operators/python.py", line 238, in execute
    return_value = self.execute_callable()
                   ^^^^^^^^^^^^^^^^^^^^^^^
  File "/home/airflow/.local/lib/python3.12/site-packages/airflow/operators/python.py", line 256, in execute_callable
    return runner.run(*self.op_args, **self.op_kwargs)
           ^^^^^^^^^^^^^^^^^^^^^^^^^^^^^^^^^^^^^^^^^^^
  File "/home/airflow/.local/lib/python3.12/site-packages/airflow/utils/operator_helpers.py", line 252, in run
    return self.func(*args, **kwargs)
           ^^^^^^^^^^^^^^^^^^^^^^^^^^
  File "/opt/airflow/dags/idp.py", line 139, in fetch_from_mongo
    raise Exception(f"The following error occurred: {str(e)}")
Exception: The following error occurred: HTTPConnectionPool(host='localhost', port=4000): Max retries exceeded with url: /socket.io/?transport=polling&EIO=4&t=1740297485.6925874 (Caused by NewConnectionError('<urllib3.connection.HTTPConnection object at 0xffff628e8410>: Failed to establish a new connection: [Errno 111] Connection refused'))
[2025-02-23T07:58:05.786+0000] {local_task_job_runner.py:266} INFO - Task exited with return code 1
[2025-02-23T07:58:05.803+0000] {taskinstance.py:3895} INFO - 0 downstream tasks scheduled from follow-on schedule check
[2025-02-23T07:58:05.804+0000] {local_task_job_runner.py:245} INFO - ::endgroup::
