[2025-02-07T06:30:24.812+0000] {local_task_job_runner.py:123} INFO - ::group::Pre task execution logs
[2025-02-07T06:30:24.821+0000] {taskinstance.py:2613} INFO - Dependencies all met for dep_context=non-requeueable deps ti=<TaskInstance: idp.rabbitmq_consumer manual__2025-02-07T06:30:23.490902+00:00 [queued]>
[2025-02-07T06:30:24.824+0000] {taskinstance.py:2613} INFO - Dependencies all met for dep_context=requeueable deps ti=<TaskInstance: idp.rabbitmq_consumer manual__2025-02-07T06:30:23.490902+00:00 [queued]>
[2025-02-07T06:30:24.825+0000] {taskinstance.py:2866} INFO - Starting attempt 1 of 2
[2025-02-07T06:30:24.831+0000] {taskinstance.py:2889} INFO - Executing <Task(PythonOperator): rabbitmq_consumer> on 2025-02-07 06:30:23.490902+00:00
[2025-02-07T06:30:24.836+0000] {warnings.py:112} WARNING - /home/***/.local/lib/python3.12/site-packages/***/task/task_runner/standard_task_runner.py:70: DeprecationWarning: This process (pid=1120) is multi-threaded, use of fork() may lead to deadlocks in the child.
  pid = os.fork()

[2025-02-07T06:30:24.838+0000] {standard_task_runner.py:72} INFO - Started process 1121 to run task
[2025-02-07T06:30:24.839+0000] {standard_task_runner.py:104} INFO - Running: ['***', 'tasks', 'run', 'idp', 'rabbitmq_consumer', 'manual__2025-02-07T06:30:23.490902+00:00', '--job-id', '216', '--raw', '--subdir', 'DAGS_FOLDER/idp.py', '--cfg-path', '/tmp/tmpr3gx033u']
[2025-02-07T06:30:24.840+0000] {standard_task_runner.py:105} INFO - Job 216: Subtask rabbitmq_consumer
[2025-02-07T06:30:24.870+0000] {task_command.py:467} INFO - Running <TaskInstance: idp.rabbitmq_consumer manual__2025-02-07T06:30:23.490902+00:00 [running]> on host 3aa1f743f988
[2025-02-07T06:30:24.920+0000] {taskinstance.py:3132} INFO - Exporting env vars: AIRFLOW_CTX_DAG_OWNER='***' AIRFLOW_CTX_DAG_ID='idp' AIRFLOW_CTX_TASK_ID='rabbitmq_consumer' AIRFLOW_CTX_EXECUTION_DATE='2025-02-07T06:30:23.490902+00:00' AIRFLOW_CTX_TRY_NUMBER='1' AIRFLOW_CTX_DAG_RUN_ID='manual__2025-02-07T06:30:23.490902+00:00'
[2025-02-07T06:30:24.921+0000] {logging_mixin.py:190} INFO - Task instance is in running state
[2025-02-07T06:30:24.921+0000] {logging_mixin.py:190} INFO -  Previous state of the Task instance: queued
[2025-02-07T06:30:24.921+0000] {logging_mixin.py:190} INFO - Current task name:rabbitmq_consumer state:running start_date:2025-02-07 06:30:24.821359+00:00
[2025-02-07T06:30:24.921+0000] {logging_mixin.py:190} INFO - Dag name:idp and current dag run status:running
[2025-02-07T06:30:24.921+0000] {taskinstance.py:731} INFO - ::endgroup::
[2025-02-07T06:30:24.923+0000] {logging_mixin.py:190} INFO - RABBITMQ_URL: amqp://rabbitmq:rabbitmq@localhost:15672
[2025-02-07T06:30:24.925+0000] {connection_workflow.py:179} INFO - Pika version 1.3.2 connecting to ('::1', 15672, 0, 0)
[2025-02-07T06:30:24.926+0000] {io_services_utils.py:349} ERROR - Socket failed to connect: <socket.socket fd=93, family=10, type=1, proto=6, laddr=('::1', 58430, 0, 0)>; error=111 (Connection refused)
[2025-02-07T06:30:24.926+0000] {connection_workflow.py:375} ERROR - TCP Connection attempt failed: ConnectionRefusedError(111, 'Connection refused'); dest=(10, 1, 6, '', ('::1', 15672, 0, 0))
[2025-02-07T06:30:24.926+0000] {connection_workflow.py:291} ERROR - AMQPConnector - reporting failure: AMQPConnectorSocketConnectError: ConnectionRefusedError(111, 'Connection refused')
[2025-02-07T06:30:24.928+0000] {connection_workflow.py:179} INFO - Pika version 1.3.2 connecting to ('127.0.0.1', 15672)
[2025-02-07T06:30:24.929+0000] {io_services_utils.py:349} ERROR - Socket failed to connect: <socket.socket fd=93, family=2, type=1, proto=6, laddr=('127.0.0.1', 60726)>; error=111 (Connection refused)
[2025-02-07T06:30:24.929+0000] {connection_workflow.py:375} ERROR - TCP Connection attempt failed: ConnectionRefusedError(111, 'Connection refused'); dest=(2, 1, 6, '', ('127.0.0.1', 15672))
[2025-02-07T06:30:24.929+0000] {connection_workflow.py:291} ERROR - AMQPConnector - reporting failure: AMQPConnectorSocketConnectError: ConnectionRefusedError(111, 'Connection refused')
[2025-02-07T06:30:24.929+0000] {connection_workflow.py:746} ERROR - AMQP connection workflow failed: AMQPConnectionWorkflowFailed: 2 exceptions in all; last exception - AMQPConnectorSocketConnectError: ConnectionRefusedError(111, 'Connection refused'); first exception - AMQPConnectorSocketConnectError: ConnectionRefusedError(111, 'Connection refused').
[2025-02-07T06:30:24.930+0000] {connection_workflow.py:723} ERROR - AMQPConnectionWorkflow - reporting failure: AMQPConnectionWorkflowFailed: 2 exceptions in all; last exception - AMQPConnectorSocketConnectError: ConnectionRefusedError(111, 'Connection refused'); first exception - AMQPConnectorSocketConnectError: ConnectionRefusedError(111, 'Connection refused')
[2025-02-07T06:30:24.930+0000] {blocking_connection.py:450} ERROR - Connection workflow failed: AMQPConnectionWorkflowFailed: 2 exceptions in all; last exception - AMQPConnectorSocketConnectError: ConnectionRefusedError(111, 'Connection refused'); first exception - AMQPConnectorSocketConnectError: ConnectionRefusedError(111, 'Connection refused')
[2025-02-07T06:30:24.930+0000] {blocking_connection.py:457} ERROR - Error in _create_connection().
Traceback (most recent call last):
  File "/home/airflow/.local/lib/python3.12/site-packages/pika/adapters/blocking_connection.py", line 451, in _create_connection
    raise self._reap_last_connection_workflow_error(error)
pika.exceptions.AMQPConnectionError
[2025-02-07T06:30:24.931+0000] {logging_mixin.py:190} INFO - Error in listener: 
[2025-02-07T06:30:24.931+0000] {taskinstance.py:3311} ERROR - Task failed with exception
Traceback (most recent call last):
  File "/home/airflow/.local/lib/python3.12/site-packages/airflow/models/taskinstance.py", line 767, in _execute_task
    result = _execute_callable(context=context, **execute_callable_kwargs)
             ^^^^^^^^^^^^^^^^^^^^^^^^^^^^^^^^^^^^^^^^^^^^^^^^^^^^^^^^^^^^^
  File "/home/airflow/.local/lib/python3.12/site-packages/airflow/models/taskinstance.py", line 733, in _execute_callable
    return ExecutionCallableRunner(
           ^^^^^^^^^^^^^^^^^^^^^^^^
  File "/home/airflow/.local/lib/python3.12/site-packages/airflow/utils/operator_helpers.py", line 252, in run
    return self.func(*args, **kwargs)
           ^^^^^^^^^^^^^^^^^^^^^^^^^^
  File "/home/airflow/.local/lib/python3.12/site-packages/airflow/models/baseoperator.py", line 422, in wrapper
    return func(self, *args, **kwargs)
           ^^^^^^^^^^^^^^^^^^^^^^^^^^^
  File "/home/airflow/.local/lib/python3.12/site-packages/airflow/operators/python.py", line 238, in execute
    return_value = self.execute_callable()
                   ^^^^^^^^^^^^^^^^^^^^^^^
  File "/home/airflow/.local/lib/python3.12/site-packages/airflow/operators/python.py", line 256, in execute_callable
    return runner.run(*self.op_args, **self.op_kwargs)
           ^^^^^^^^^^^^^^^^^^^^^^^^^^^^^^^^^^^^^^^^^^^
  File "/home/airflow/.local/lib/python3.12/site-packages/airflow/utils/operator_helpers.py", line 252, in run
    return self.func(*args, **kwargs)
           ^^^^^^^^^^^^^^^^^^^^^^^^^^
  File "/opt/airflow/dags/idp.py", line 46, in rabbitmq_consumer
    connection.close()
    ^^^^^^^^^^
UnboundLocalError: cannot access local variable 'connection' where it is not associated with a value
[2025-02-07T06:30:24.942+0000] {logging_mixin.py:190} INFO - Task instance in failure state
[2025-02-07T06:30:24.942+0000] {logging_mixin.py:190} INFO - Task start:2025-02-07 06:30:24.821359+00:00 end:2025-02-07 06:30:24.941739+00:00 duration:0.12038
[2025-02-07T06:30:24.942+0000] {logging_mixin.py:190} INFO - Task:<Task(PythonOperator): rabbitmq_consumer> dag:<DAG: idp> dagrun:<DagRun idp @ 2025-02-07 06:30:23.490902+00:00: manual__2025-02-07T06:30:23.490902+00:00, state:running, queued_at: 2025-02-07 06:30:23.500627+00:00. externally triggered: True>
[2025-02-07T06:30:24.942+0000] {logging_mixin.py:190} INFO - Failure caused by cannot access local variable 'connection' where it is not associated with a value
[2025-02-07T06:30:24.942+0000] {taskinstance.py:1225} INFO - Marking task as UP_FOR_RETRY. dag_id=idp, task_id=rabbitmq_consumer, run_id=manual__2025-02-07T06:30:23.490902+00:00, execution_date=20250207T063023, start_date=20250207T063024, end_date=20250207T063024
[2025-02-07T06:30:24.951+0000] {taskinstance.py:340} INFO - ::group::Post task execution logs
[2025-02-07T06:30:24.951+0000] {standard_task_runner.py:124} ERROR - Failed to execute job 216 for task rabbitmq_consumer (cannot access local variable 'connection' where it is not associated with a value; 1121)
Traceback (most recent call last):
  File "/home/airflow/.local/lib/python3.12/site-packages/airflow/task/task_runner/standard_task_runner.py", line 117, in _start_by_fork
    ret = args.func(args, dag=self.dag)
          ^^^^^^^^^^^^^^^^^^^^^^^^^^^^^
  File "/home/airflow/.local/lib/python3.12/site-packages/airflow/cli/cli_config.py", line 49, in command
    return func(*args, **kwargs)
           ^^^^^^^^^^^^^^^^^^^^^
  File "/home/airflow/.local/lib/python3.12/site-packages/airflow/utils/cli.py", line 116, in wrapper
    return f(*args, **kwargs)
           ^^^^^^^^^^^^^^^^^^
  File "/home/airflow/.local/lib/python3.12/site-packages/airflow/cli/commands/task_command.py", line 483, in task_run
    task_return_code = _run_task_by_selected_method(args, _dag, ti)
                       ^^^^^^^^^^^^^^^^^^^^^^^^^^^^^^^^^^^^^^^^^^^^
  File "/home/airflow/.local/lib/python3.12/site-packages/airflow/cli/commands/task_command.py", line 256, in _run_task_by_selected_method
    return _run_raw_task(args, ti)
           ^^^^^^^^^^^^^^^^^^^^^^^
  File "/home/airflow/.local/lib/python3.12/site-packages/airflow/cli/commands/task_command.py", line 341, in _run_raw_task
    return ti._run_raw_task(
           ^^^^^^^^^^^^^^^^^
  File "/home/airflow/.local/lib/python3.12/site-packages/airflow/utils/session.py", line 97, in wrapper
    return func(*args, session=session, **kwargs)
           ^^^^^^^^^^^^^^^^^^^^^^^^^^^^^^^^^^^^^^
  File "/home/airflow/.local/lib/python3.12/site-packages/airflow/models/taskinstance.py", line 3005, in _run_raw_task
    return _run_raw_task(
           ^^^^^^^^^^^^^^
  File "/home/airflow/.local/lib/python3.12/site-packages/airflow/models/taskinstance.py", line 273, in _run_raw_task
    TaskInstance._execute_task_with_callbacks(
  File "/home/airflow/.local/lib/python3.12/site-packages/airflow/models/taskinstance.py", line 3159, in _execute_task_with_callbacks
    result = self._execute_task(context, task_orig)
             ^^^^^^^^^^^^^^^^^^^^^^^^^^^^^^^^^^^^^^
  File "/home/airflow/.local/lib/python3.12/site-packages/airflow/models/taskinstance.py", line 3183, in _execute_task
    return _execute_task(self, context, task_orig)
           ^^^^^^^^^^^^^^^^^^^^^^^^^^^^^^^^^^^^^^^
  File "/home/airflow/.local/lib/python3.12/site-packages/airflow/models/taskinstance.py", line 767, in _execute_task
    result = _execute_callable(context=context, **execute_callable_kwargs)
             ^^^^^^^^^^^^^^^^^^^^^^^^^^^^^^^^^^^^^^^^^^^^^^^^^^^^^^^^^^^^^
  File "/home/airflow/.local/lib/python3.12/site-packages/airflow/models/taskinstance.py", line 733, in _execute_callable
    return ExecutionCallableRunner(
           ^^^^^^^^^^^^^^^^^^^^^^^^
  File "/home/airflow/.local/lib/python3.12/site-packages/airflow/utils/operator_helpers.py", line 252, in run
    return self.func(*args, **kwargs)
           ^^^^^^^^^^^^^^^^^^^^^^^^^^
  File "/home/airflow/.local/lib/python3.12/site-packages/airflow/models/baseoperator.py", line 422, in wrapper
    return func(self, *args, **kwargs)
           ^^^^^^^^^^^^^^^^^^^^^^^^^^^
  File "/home/airflow/.local/lib/python3.12/site-packages/airflow/operators/python.py", line 238, in execute
    return_value = self.execute_callable()
                   ^^^^^^^^^^^^^^^^^^^^^^^
  File "/home/airflow/.local/lib/python3.12/site-packages/airflow/operators/python.py", line 256, in execute_callable
    return runner.run(*self.op_args, **self.op_kwargs)
           ^^^^^^^^^^^^^^^^^^^^^^^^^^^^^^^^^^^^^^^^^^^
  File "/home/airflow/.local/lib/python3.12/site-packages/airflow/utils/operator_helpers.py", line 252, in run
    return self.func(*args, **kwargs)
           ^^^^^^^^^^^^^^^^^^^^^^^^^^
  File "/opt/airflow/dags/idp.py", line 46, in rabbitmq_consumer
    connection.close()
    ^^^^^^^^^^
UnboundLocalError: cannot access local variable 'connection' where it is not associated with a value
[2025-02-07T06:30:24.979+0000] {local_task_job_runner.py:266} INFO - Task exited with return code 1
[2025-02-07T06:30:24.991+0000] {taskinstance.py:3895} INFO - 0 downstream tasks scheduled from follow-on schedule check
[2025-02-07T06:30:24.992+0000] {local_task_job_runner.py:245} INFO - ::endgroup::
