[2025-02-04T05:46:36.366+0000] {local_task_job_runner.py:123} INFO - ::group::Pre task execution logs
[2025-02-04T05:46:36.373+0000] {taskinstance.py:2613} INFO - Dependencies all met for dep_context=non-requeueable deps ti=<TaskInstance: idp_fetch_mongo.fetch_from_mongo scheduled__2025-02-03T00:00:00+00:00 [queued]>
[2025-02-04T05:46:36.377+0000] {taskinstance.py:2613} INFO - Dependencies all met for dep_context=requeueable deps ti=<TaskInstance: idp_fetch_mongo.fetch_from_mongo scheduled__2025-02-03T00:00:00+00:00 [queued]>
[2025-02-04T05:46:36.377+0000] {taskinstance.py:2866} INFO - Starting attempt 1 of 2
[2025-02-04T05:46:36.386+0000] {taskinstance.py:2889} INFO - Executing <Task(PythonOperator): fetch_from_mongo> on 2025-02-03 00:00:00+00:00
[2025-02-04T05:46:36.393+0000] {warnings.py:112} WARNING - /home/***/.local/lib/python3.12/site-packages/***/task/task_runner/standard_task_runner.py:70: DeprecationWarning: This process (pid=62) is multi-threaded, use of fork() may lead to deadlocks in the child.
  pid = os.fork()

[2025-02-04T05:46:36.394+0000] {standard_task_runner.py:72} INFO - Started process 63 to run task
[2025-02-04T05:46:36.394+0000] {standard_task_runner.py:104} INFO - Running: ['***', 'tasks', 'run', 'idp_fetch_mongo', 'fetch_from_mongo', 'scheduled__2025-02-03T00:00:00+00:00', '--job-id', '140', '--raw', '--subdir', 'DAGS_FOLDER/idp.py', '--cfg-path', '/tmp/tmp1vreyd_7']
[2025-02-04T05:46:36.395+0000] {standard_task_runner.py:105} INFO - Job 140: Subtask fetch_from_mongo
[2025-02-04T05:46:36.421+0000] {task_command.py:467} INFO - Running <TaskInstance: idp_fetch_mongo.fetch_from_mongo scheduled__2025-02-03T00:00:00+00:00 [running]> on host 3aa1f743f988
[2025-02-04T05:46:36.468+0000] {taskinstance.py:3132} INFO - Exporting env vars: AIRFLOW_CTX_DAG_OWNER='***' AIRFLOW_CTX_DAG_ID='idp_fetch_mongo' AIRFLOW_CTX_TASK_ID='fetch_from_mongo' AIRFLOW_CTX_EXECUTION_DATE='2025-02-03T00:00:00+00:00' AIRFLOW_CTX_TRY_NUMBER='1' AIRFLOW_CTX_DAG_RUN_ID='scheduled__2025-02-03T00:00:00+00:00'
[2025-02-04T05:46:36.468+0000] {logging_mixin.py:190} INFO - Task instance is in running state
[2025-02-04T05:46:36.469+0000] {logging_mixin.py:190} INFO -  Previous state of the Task instance: queued
[2025-02-04T05:46:36.469+0000] {logging_mixin.py:190} INFO - Current task name:fetch_from_mongo state:running start_date:2025-02-04 05:46:36.373655+00:00
[2025-02-04T05:46:36.469+0000] {logging_mixin.py:190} INFO - Dag name:idp_fetch_mongo and current dag run status:running
[2025-02-04T05:46:36.469+0000] {taskinstance.py:731} INFO - ::endgroup::
[2025-02-04T05:46:36.476+0000] {base.py:84} INFO - Retrieving connection 'mongoid'
[2025-02-04T05:46:36.477+0000] {logging_mixin.py:190} INFO - Error fetching from MongoDB: Bad database name "/admin:***@cluster0"
[2025-02-04T05:46:36.478+0000] {python.py:240} INFO - Done. Returned value was: []
[2025-02-04T05:46:36.488+0000] {taskinstance.py:340} INFO - ::group::Post task execution logs
[2025-02-04T05:46:36.488+0000] {taskinstance.py:352} INFO - Marking task as SUCCESS. dag_id=idp_fetch_mongo, task_id=fetch_from_mongo, run_id=scheduled__2025-02-03T00:00:00+00:00, execution_date=20250203T000000, start_date=20250204T054636, end_date=20250204T054636
[2025-02-04T05:46:36.493+0000] {logging_mixin.py:190} INFO - Task instance in success state
[2025-02-04T05:46:36.493+0000] {logging_mixin.py:190} INFO -  Previous state of the Task instance: running
[2025-02-04T05:46:36.493+0000] {logging_mixin.py:190} INFO - Dag name:idp_fetch_mongo queued_at:2025-02-04 05:46:32.413151+00:00
[2025-02-04T05:46:36.493+0000] {logging_mixin.py:190} INFO - Task hostname:3aa1f743f988 operator:PythonOperator
[2025-02-04T05:46:36.537+0000] {local_task_job_runner.py:266} INFO - Task exited with return code 0
[2025-02-04T05:46:36.545+0000] {taskinstance.py:3895} INFO - 0 downstream tasks scheduled from follow-on schedule check
[2025-02-04T05:46:36.547+0000] {local_task_job_runner.py:245} INFO - ::endgroup::
[2025-02-04T13:31:56.953+0000] {local_task_job_runner.py:123} INFO - ::group::Pre task execution logs
[2025-02-04T13:31:56.969+0000] {taskinstance.py:2613} INFO - Dependencies all met for dep_context=non-requeueable deps ti=<TaskInstance: idp_fetch_mongo.fetch_from_mongo scheduled__2025-02-03T00:00:00+00:00 [queued]>
[2025-02-04T13:31:56.975+0000] {taskinstance.py:2613} INFO - Dependencies all met for dep_context=requeueable deps ti=<TaskInstance: idp_fetch_mongo.fetch_from_mongo scheduled__2025-02-03T00:00:00+00:00 [queued]>
[2025-02-04T13:31:56.975+0000] {taskinstance.py:2866} INFO - Starting attempt 1 of 2
[2025-02-04T13:31:56.984+0000] {taskinstance.py:2889} INFO - Executing <Task(PythonOperator): fetch_from_mongo> on 2025-02-03 00:00:00+00:00
[2025-02-04T13:31:56.994+0000] {warnings.py:112} WARNING - /home/***/.local/lib/python3.12/site-packages/***/task/task_runner/standard_task_runner.py:70: DeprecationWarning: This process (pid=4552) is multi-threaded, use of fork() may lead to deadlocks in the child.
  pid = os.fork()

[2025-02-04T13:31:56.996+0000] {standard_task_runner.py:72} INFO - Started process 4553 to run task
[2025-02-04T13:31:56.996+0000] {standard_task_runner.py:104} INFO - Running: ['***', 'tasks', 'run', 'idp_fetch_mongo', 'fetch_from_mongo', 'scheduled__2025-02-03T00:00:00+00:00', '--job-id', '167', '--raw', '--subdir', 'DAGS_FOLDER/idp.py', '--cfg-path', '/tmp/tmpgv_d80hn']
[2025-02-04T13:31:56.997+0000] {standard_task_runner.py:105} INFO - Job 167: Subtask fetch_from_mongo
[2025-02-04T13:31:57.048+0000] {task_command.py:467} INFO - Running <TaskInstance: idp_fetch_mongo.fetch_from_mongo scheduled__2025-02-03T00:00:00+00:00 [running]> on host 3aa1f743f988
[2025-02-04T13:31:57.110+0000] {taskinstance.py:3132} INFO - Exporting env vars: AIRFLOW_CTX_DAG_OWNER='***' AIRFLOW_CTX_DAG_ID='idp_fetch_mongo' AIRFLOW_CTX_TASK_ID='fetch_from_mongo' AIRFLOW_CTX_EXECUTION_DATE='2025-02-03T00:00:00+00:00' AIRFLOW_CTX_TRY_NUMBER='1' AIRFLOW_CTX_DAG_RUN_ID='scheduled__2025-02-03T00:00:00+00:00'
[2025-02-04T13:31:57.111+0000] {logging_mixin.py:190} INFO - Task instance is in running state
[2025-02-04T13:31:57.111+0000] {logging_mixin.py:190} INFO -  Previous state of the Task instance: queued
[2025-02-04T13:31:57.111+0000] {logging_mixin.py:190} INFO - Current task name:fetch_from_mongo state:running start_date:2025-02-04 13:31:56.969637+00:00
[2025-02-04T13:31:57.112+0000] {logging_mixin.py:190} INFO - Dag name:idp_fetch_mongo and current dag run status:running
[2025-02-04T13:31:57.112+0000] {taskinstance.py:731} INFO - ::endgroup::
[2025-02-04T13:31:57.113+0000] {logging_mixin.py:190} INFO - Connecting to MongoDB at:  None
[2025-02-04T13:31:57.124+0000] {logging_mixin.py:190} INFO - No projectId provided in DAG run config.
[2025-02-04T13:31:57.124+0000] {python.py:240} INFO - Done. Returned value was: []
[2025-02-04T13:31:57.145+0000] {taskinstance.py:340} INFO - ::group::Post task execution logs
[2025-02-04T13:31:57.146+0000] {taskinstance.py:352} INFO - Marking task as SUCCESS. dag_id=idp_fetch_mongo, task_id=fetch_from_mongo, run_id=scheduled__2025-02-03T00:00:00+00:00, execution_date=20250203T000000, start_date=20250204T133156, end_date=20250204T133157
[2025-02-04T13:31:57.155+0000] {logging_mixin.py:190} INFO - Task instance in success state
[2025-02-04T13:31:57.157+0000] {logging_mixin.py:190} INFO -  Previous state of the Task instance: running
[2025-02-04T13:31:57.158+0000] {logging_mixin.py:190} INFO - Dag name:idp_fetch_mongo queued_at:2025-02-04 13:31:55.000935+00:00
[2025-02-04T13:31:57.158+0000] {logging_mixin.py:190} INFO - Task hostname:3aa1f743f988 operator:PythonOperator
[2025-02-04T13:31:57.179+0000] {local_task_job_runner.py:266} INFO - Task exited with return code 0
[2025-02-04T13:31:57.193+0000] {taskinstance.py:3895} INFO - 0 downstream tasks scheduled from follow-on schedule check
[2025-02-04T13:31:57.194+0000] {local_task_job_runner.py:245} INFO - ::endgroup::
[2025-02-04T13:41:32.263+0000] {local_task_job_runner.py:123} INFO - ::group::Pre task execution logs
[2025-02-04T13:41:32.276+0000] {taskinstance.py:2613} INFO - Dependencies all met for dep_context=non-requeueable deps ti=<TaskInstance: idp_fetch_mongo.fetch_from_mongo scheduled__2025-02-03T00:00:00+00:00 [queued]>
[2025-02-04T13:41:32.285+0000] {taskinstance.py:2613} INFO - Dependencies all met for dep_context=requeueable deps ti=<TaskInstance: idp_fetch_mongo.fetch_from_mongo scheduled__2025-02-03T00:00:00+00:00 [queued]>
[2025-02-04T13:41:32.285+0000] {taskinstance.py:2866} INFO - Starting attempt 1 of 2
[2025-02-04T13:41:32.293+0000] {taskinstance.py:2889} INFO - Executing <Task(PythonOperator): fetch_from_mongo> on 2025-02-03 00:00:00+00:00
[2025-02-04T13:41:32.301+0000] {warnings.py:112} WARNING - /home/***/.local/lib/python3.12/site-packages/***/task/task_runner/standard_task_runner.py:70: DeprecationWarning: This process (pid=4731) is multi-threaded, use of fork() may lead to deadlocks in the child.
  pid = os.fork()

[2025-02-04T13:41:32.303+0000] {standard_task_runner.py:72} INFO - Started process 4734 to run task
[2025-02-04T13:41:32.307+0000] {standard_task_runner.py:104} INFO - Running: ['***', 'tasks', 'run', 'idp_fetch_mongo', 'fetch_from_mongo', 'scheduled__2025-02-03T00:00:00+00:00', '--job-id', '179', '--raw', '--subdir', 'DAGS_FOLDER/idp.py', '--cfg-path', '/tmp/tmpj0tjn6up']
[2025-02-04T13:41:32.310+0000] {standard_task_runner.py:105} INFO - Job 179: Subtask fetch_from_mongo
[2025-02-04T13:41:32.357+0000] {task_command.py:467} INFO - Running <TaskInstance: idp_fetch_mongo.fetch_from_mongo scheduled__2025-02-03T00:00:00+00:00 [running]> on host 3aa1f743f988
[2025-02-04T13:41:32.414+0000] {taskinstance.py:3132} INFO - Exporting env vars: AIRFLOW_CTX_DAG_OWNER='***' AIRFLOW_CTX_DAG_ID='idp_fetch_mongo' AIRFLOW_CTX_TASK_ID='fetch_from_mongo' AIRFLOW_CTX_EXECUTION_DATE='2025-02-03T00:00:00+00:00' AIRFLOW_CTX_TRY_NUMBER='1' AIRFLOW_CTX_DAG_RUN_ID='scheduled__2025-02-03T00:00:00+00:00'
[2025-02-04T13:41:32.415+0000] {logging_mixin.py:190} INFO - Task instance is in running state
[2025-02-04T13:41:32.416+0000] {logging_mixin.py:190} INFO -  Previous state of the Task instance: queued
[2025-02-04T13:41:32.416+0000] {logging_mixin.py:190} INFO - Current task name:fetch_from_mongo state:running start_date:2025-02-04 13:41:32.277440+00:00
[2025-02-04T13:41:32.416+0000] {logging_mixin.py:190} INFO - Dag name:idp_fetch_mongo and current dag run status:running
[2025-02-04T13:41:32.416+0000] {taskinstance.py:731} INFO - ::endgroup::
[2025-02-04T13:41:32.418+0000] {taskinstance.py:3311} ERROR - Task failed with exception
Traceback (most recent call last):
  File "/opt/airflow/dags/idp.py", line 18, in fetch_from_mongo
    raise Exception("MONGODB_URI is not set")
Exception: MONGODB_URI is not set

During handling of the above exception, another exception occurred:

Traceback (most recent call last):
  File "/opt/airflow/dags/idp.py", line 40, in fetch_from_mongo
    raise Exception(f"The following error occurred: {str(e)}")
Exception: The following error occurred: MONGODB_URI is not set

During handling of the above exception, another exception occurred:

Traceback (most recent call last):
  File "/home/airflow/.local/lib/python3.12/site-packages/airflow/models/taskinstance.py", line 767, in _execute_task
    result = _execute_callable(context=context, **execute_callable_kwargs)
             ^^^^^^^^^^^^^^^^^^^^^^^^^^^^^^^^^^^^^^^^^^^^^^^^^^^^^^^^^^^^^
  File "/home/airflow/.local/lib/python3.12/site-packages/airflow/models/taskinstance.py", line 733, in _execute_callable
    return ExecutionCallableRunner(
           ^^^^^^^^^^^^^^^^^^^^^^^^
  File "/home/airflow/.local/lib/python3.12/site-packages/airflow/utils/operator_helpers.py", line 252, in run
    return self.func(*args, **kwargs)
           ^^^^^^^^^^^^^^^^^^^^^^^^^^
  File "/home/airflow/.local/lib/python3.12/site-packages/airflow/models/baseoperator.py", line 422, in wrapper
    return func(self, *args, **kwargs)
           ^^^^^^^^^^^^^^^^^^^^^^^^^^^
  File "/home/airflow/.local/lib/python3.12/site-packages/airflow/operators/python.py", line 238, in execute
    return_value = self.execute_callable()
                   ^^^^^^^^^^^^^^^^^^^^^^^
  File "/home/airflow/.local/lib/python3.12/site-packages/airflow/operators/python.py", line 256, in execute_callable
    return runner.run(*self.op_args, **self.op_kwargs)
           ^^^^^^^^^^^^^^^^^^^^^^^^^^^^^^^^^^^^^^^^^^^
  File "/home/airflow/.local/lib/python3.12/site-packages/airflow/utils/operator_helpers.py", line 252, in run
    return self.func(*args, **kwargs)
           ^^^^^^^^^^^^^^^^^^^^^^^^^^
  File "/opt/airflow/dags/idp.py", line 43, in fetch_from_mongo
    client.close()  # Close client only after fetching data
    ^^^^^^
UnboundLocalError: cannot access local variable 'client' where it is not associated with a value
[2025-02-04T13:41:32.429+0000] {logging_mixin.py:190} INFO - Task instance in failure state
[2025-02-04T13:41:32.430+0000] {logging_mixin.py:190} INFO - Task start:2025-02-04 13:41:32.277440+00:00 end:2025-02-04 13:41:32.429437+00:00 duration:0.151997
[2025-02-04T13:41:32.430+0000] {logging_mixin.py:190} INFO - Task:<Task(PythonOperator): fetch_from_mongo> dag:<DAG: idp_fetch_mongo> dagrun:<DagRun idp_fetch_mongo @ 2025-02-03 00:00:00+00:00: scheduled__2025-02-03T00:00:00+00:00, state:running, queued_at: 2025-02-04 13:41:30.262420+00:00. externally triggered: False>
[2025-02-04T13:41:32.430+0000] {logging_mixin.py:190} INFO - Failure caused by cannot access local variable 'client' where it is not associated with a value
[2025-02-04T13:41:32.431+0000] {taskinstance.py:1225} INFO - Marking task as UP_FOR_RETRY. dag_id=idp_fetch_mongo, task_id=fetch_from_mongo, run_id=scheduled__2025-02-03T00:00:00+00:00, execution_date=20250203T000000, start_date=20250204T134132, end_date=20250204T134132
[2025-02-04T13:41:32.444+0000] {taskinstance.py:340} INFO - ::group::Post task execution logs
[2025-02-04T13:41:32.445+0000] {standard_task_runner.py:124} ERROR - Failed to execute job 179 for task fetch_from_mongo (cannot access local variable 'client' where it is not associated with a value; 4734)
Traceback (most recent call last):
  File "/opt/airflow/dags/idp.py", line 18, in fetch_from_mongo
    raise Exception("MONGODB_URI is not set")
Exception: MONGODB_URI is not set

During handling of the above exception, another exception occurred:

Traceback (most recent call last):
  File "/opt/airflow/dags/idp.py", line 40, in fetch_from_mongo
    raise Exception(f"The following error occurred: {str(e)}")
Exception: The following error occurred: MONGODB_URI is not set

During handling of the above exception, another exception occurred:

Traceback (most recent call last):
  File "/home/airflow/.local/lib/python3.12/site-packages/airflow/task/task_runner/standard_task_runner.py", line 117, in _start_by_fork
    ret = args.func(args, dag=self.dag)
          ^^^^^^^^^^^^^^^^^^^^^^^^^^^^^
  File "/home/airflow/.local/lib/python3.12/site-packages/airflow/cli/cli_config.py", line 49, in command
    return func(*args, **kwargs)
           ^^^^^^^^^^^^^^^^^^^^^
  File "/home/airflow/.local/lib/python3.12/site-packages/airflow/utils/cli.py", line 116, in wrapper
    return f(*args, **kwargs)
           ^^^^^^^^^^^^^^^^^^
  File "/home/airflow/.local/lib/python3.12/site-packages/airflow/cli/commands/task_command.py", line 483, in task_run
    task_return_code = _run_task_by_selected_method(args, _dag, ti)
                       ^^^^^^^^^^^^^^^^^^^^^^^^^^^^^^^^^^^^^^^^^^^^
  File "/home/airflow/.local/lib/python3.12/site-packages/airflow/cli/commands/task_command.py", line 256, in _run_task_by_selected_method
    return _run_raw_task(args, ti)
           ^^^^^^^^^^^^^^^^^^^^^^^
  File "/home/airflow/.local/lib/python3.12/site-packages/airflow/cli/commands/task_command.py", line 341, in _run_raw_task
    return ti._run_raw_task(
           ^^^^^^^^^^^^^^^^^
  File "/home/airflow/.local/lib/python3.12/site-packages/airflow/utils/session.py", line 97, in wrapper
    return func(*args, session=session, **kwargs)
           ^^^^^^^^^^^^^^^^^^^^^^^^^^^^^^^^^^^^^^
  File "/home/airflow/.local/lib/python3.12/site-packages/airflow/models/taskinstance.py", line 3005, in _run_raw_task
    return _run_raw_task(
           ^^^^^^^^^^^^^^
  File "/home/airflow/.local/lib/python3.12/site-packages/airflow/models/taskinstance.py", line 273, in _run_raw_task
    TaskInstance._execute_task_with_callbacks(
  File "/home/airflow/.local/lib/python3.12/site-packages/airflow/models/taskinstance.py", line 3159, in _execute_task_with_callbacks
    result = self._execute_task(context, task_orig)
             ^^^^^^^^^^^^^^^^^^^^^^^^^^^^^^^^^^^^^^
  File "/home/airflow/.local/lib/python3.12/site-packages/airflow/models/taskinstance.py", line 3183, in _execute_task
    return _execute_task(self, context, task_orig)
           ^^^^^^^^^^^^^^^^^^^^^^^^^^^^^^^^^^^^^^^
  File "/home/airflow/.local/lib/python3.12/site-packages/airflow/models/taskinstance.py", line 767, in _execute_task
    result = _execute_callable(context=context, **execute_callable_kwargs)
             ^^^^^^^^^^^^^^^^^^^^^^^^^^^^^^^^^^^^^^^^^^^^^^^^^^^^^^^^^^^^^
  File "/home/airflow/.local/lib/python3.12/site-packages/airflow/models/taskinstance.py", line 733, in _execute_callable
    return ExecutionCallableRunner(
           ^^^^^^^^^^^^^^^^^^^^^^^^
  File "/home/airflow/.local/lib/python3.12/site-packages/airflow/utils/operator_helpers.py", line 252, in run
    return self.func(*args, **kwargs)
           ^^^^^^^^^^^^^^^^^^^^^^^^^^
  File "/home/airflow/.local/lib/python3.12/site-packages/airflow/models/baseoperator.py", line 422, in wrapper
    return func(self, *args, **kwargs)
           ^^^^^^^^^^^^^^^^^^^^^^^^^^^
  File "/home/airflow/.local/lib/python3.12/site-packages/airflow/operators/python.py", line 238, in execute
    return_value = self.execute_callable()
                   ^^^^^^^^^^^^^^^^^^^^^^^
  File "/home/airflow/.local/lib/python3.12/site-packages/airflow/operators/python.py", line 256, in execute_callable
    return runner.run(*self.op_args, **self.op_kwargs)
           ^^^^^^^^^^^^^^^^^^^^^^^^^^^^^^^^^^^^^^^^^^^
  File "/home/airflow/.local/lib/python3.12/site-packages/airflow/utils/operator_helpers.py", line 252, in run
    return self.func(*args, **kwargs)
           ^^^^^^^^^^^^^^^^^^^^^^^^^^
  File "/opt/airflow/dags/idp.py", line 43, in fetch_from_mongo
    client.close()  # Close client only after fetching data
    ^^^^^^
UnboundLocalError: cannot access local variable 'client' where it is not associated with a value
[2025-02-04T13:41:32.487+0000] {local_task_job_runner.py:266} INFO - Task exited with return code 1
[2025-02-04T13:41:32.500+0000] {taskinstance.py:3895} INFO - 0 downstream tasks scheduled from follow-on schedule check
[2025-02-04T13:41:32.501+0000] {local_task_job_runner.py:245} INFO - ::endgroup::
[2025-02-04T14:00:08.539+0000] {local_task_job_runner.py:123} INFO - ::group::Pre task execution logs
[2025-02-04T14:00:08.561+0000] {taskinstance.py:2613} INFO - Dependencies all met for dep_context=non-requeueable deps ti=<TaskInstance: idp_fetch_mongo.fetch_from_mongo scheduled__2025-02-03T00:00:00+00:00 [queued]>
[2025-02-04T14:00:08.569+0000] {taskinstance.py:2613} INFO - Dependencies all met for dep_context=requeueable deps ti=<TaskInstance: idp_fetch_mongo.fetch_from_mongo scheduled__2025-02-03T00:00:00+00:00 [queued]>
[2025-02-04T14:00:08.570+0000] {taskinstance.py:2866} INFO - Starting attempt 1 of 2
[2025-02-04T14:00:08.584+0000] {taskinstance.py:2889} INFO - Executing <Task(PythonOperator): fetch_from_mongo> on 2025-02-03 00:00:00+00:00
[2025-02-04T14:00:08.619+0000] {standard_task_runner.py:104} INFO - Running: ['***', 'tasks', 'run', 'idp_fetch_mongo', 'fetch_from_mongo', 'scheduled__2025-02-03T00:00:00+00:00', '--job-id', '189', '--raw', '--subdir', 'DAGS_FOLDER/idp.py', '--cfg-path', '/tmp/tmpuybgpneq']
[2025-02-04T14:00:08.614+0000] {warnings.py:112} WARNING - /home/***/.local/lib/python3.12/site-packages/***/task/task_runner/standard_task_runner.py:70: DeprecationWarning: This process (pid=98) is multi-threaded, use of fork() may lead to deadlocks in the child.
  pid = os.fork()

[2025-02-04T14:00:08.622+0000] {standard_task_runner.py:105} INFO - Job 189: Subtask fetch_from_mongo
[2025-02-04T14:00:08.624+0000] {standard_task_runner.py:72} INFO - Started process 99 to run task
[2025-02-04T14:00:08.779+0000] {task_command.py:467} INFO - Running <TaskInstance: idp_fetch_mongo.fetch_from_mongo scheduled__2025-02-03T00:00:00+00:00 [running]> on host 3aa1f743f988
[2025-02-04T14:00:08.870+0000] {taskinstance.py:3132} INFO - Exporting env vars: AIRFLOW_CTX_DAG_OWNER='***' AIRFLOW_CTX_DAG_ID='idp_fetch_mongo' AIRFLOW_CTX_TASK_ID='fetch_from_mongo' AIRFLOW_CTX_EXECUTION_DATE='2025-02-03T00:00:00+00:00' AIRFLOW_CTX_TRY_NUMBER='1' AIRFLOW_CTX_DAG_RUN_ID='scheduled__2025-02-03T00:00:00+00:00'
[2025-02-04T14:00:08.872+0000] {logging_mixin.py:190} INFO - Task instance is in running state
[2025-02-04T14:00:08.873+0000] {logging_mixin.py:190} INFO -  Previous state of the Task instance: queued
[2025-02-04T14:00:08.874+0000] {logging_mixin.py:190} INFO - Current task name:fetch_from_mongo state:running start_date:2025-02-04 14:00:08.561837+00:00
[2025-02-04T14:00:08.874+0000] {logging_mixin.py:190} INFO - Dag name:idp_fetch_mongo and current dag run status:running
[2025-02-04T14:00:08.875+0000] {taskinstance.py:731} INFO - ::endgroup::
[2025-02-04T14:00:08.878+0000] {logging_mixin.py:190} INFO - MONGODB_URI: None
[2025-02-04T14:00:08.879+0000] {taskinstance.py:3311} ERROR - Task failed with exception
Traceback (most recent call last):
  File "/opt/airflow/dags/idp.py", line 17, in fetch_from_mongo
    raise Exception("MONGODB_URI is not set")
Exception: MONGODB_URI is not set

During handling of the above exception, another exception occurred:

Traceback (most recent call last):
  File "/opt/airflow/dags/idp.py", line 39, in fetch_from_mongo
    raise Exception(f"The following error occurred: {str(e)}")
Exception: The following error occurred: MONGODB_URI is not set

During handling of the above exception, another exception occurred:

Traceback (most recent call last):
  File "/home/airflow/.local/lib/python3.12/site-packages/airflow/models/taskinstance.py", line 767, in _execute_task
    result = _execute_callable(context=context, **execute_callable_kwargs)
             ^^^^^^^^^^^^^^^^^^^^^^^^^^^^^^^^^^^^^^^^^^^^^^^^^^^^^^^^^^^^^
  File "/home/airflow/.local/lib/python3.12/site-packages/airflow/models/taskinstance.py", line 733, in _execute_callable
    return ExecutionCallableRunner(
           ^^^^^^^^^^^^^^^^^^^^^^^^
  File "/home/airflow/.local/lib/python3.12/site-packages/airflow/utils/operator_helpers.py", line 252, in run
    return self.func(*args, **kwargs)
           ^^^^^^^^^^^^^^^^^^^^^^^^^^
  File "/home/airflow/.local/lib/python3.12/site-packages/airflow/models/baseoperator.py", line 422, in wrapper
    return func(self, *args, **kwargs)
           ^^^^^^^^^^^^^^^^^^^^^^^^^^^
  File "/home/airflow/.local/lib/python3.12/site-packages/airflow/operators/python.py", line 238, in execute
    return_value = self.execute_callable()
                   ^^^^^^^^^^^^^^^^^^^^^^^
  File "/home/airflow/.local/lib/python3.12/site-packages/airflow/operators/python.py", line 256, in execute_callable
    return runner.run(*self.op_args, **self.op_kwargs)
           ^^^^^^^^^^^^^^^^^^^^^^^^^^^^^^^^^^^^^^^^^^^
  File "/home/airflow/.local/lib/python3.12/site-packages/airflow/utils/operator_helpers.py", line 252, in run
    return self.func(*args, **kwargs)
           ^^^^^^^^^^^^^^^^^^^^^^^^^^
  File "/opt/airflow/dags/idp.py", line 42, in fetch_from_mongo
    client.close()  # Close client only after fetching data
    ^^^^^^
UnboundLocalError: cannot access local variable 'client' where it is not associated with a value
[2025-02-04T14:00:08.909+0000] {logging_mixin.py:190} INFO - Task instance in failure state
[2025-02-04T14:00:08.910+0000] {logging_mixin.py:190} INFO - Task start:2025-02-04 14:00:08.561837+00:00 end:2025-02-04 14:00:08.907795+00:00 duration:0.345958
[2025-02-04T14:00:08.910+0000] {logging_mixin.py:190} INFO - Task:<Task(PythonOperator): fetch_from_mongo> dag:<DAG: idp_fetch_mongo> dagrun:<DagRun idp_fetch_mongo @ 2025-02-03 00:00:00+00:00: scheduled__2025-02-03T00:00:00+00:00, state:running, queued_at: 2025-02-04 14:00:05.841932+00:00. externally triggered: False>
[2025-02-04T14:00:08.938+0000] {logging_mixin.py:190} INFO - Failure caused by cannot access local variable 'client' where it is not associated with a value
[2025-02-04T14:00:08.948+0000] {taskinstance.py:1225} INFO - Marking task as UP_FOR_RETRY. dag_id=idp_fetch_mongo, task_id=fetch_from_mongo, run_id=scheduled__2025-02-03T00:00:00+00:00, execution_date=20250203T000000, start_date=20250204T140008, end_date=20250204T140008
[2025-02-04T14:00:08.995+0000] {taskinstance.py:340} INFO - ::group::Post task execution logs
[2025-02-04T14:00:08.996+0000] {standard_task_runner.py:124} ERROR - Failed to execute job 189 for task fetch_from_mongo (cannot access local variable 'client' where it is not associated with a value; 99)
Traceback (most recent call last):
  File "/opt/airflow/dags/idp.py", line 17, in fetch_from_mongo
    raise Exception("MONGODB_URI is not set")
Exception: MONGODB_URI is not set

During handling of the above exception, another exception occurred:

Traceback (most recent call last):
  File "/opt/airflow/dags/idp.py", line 39, in fetch_from_mongo
    raise Exception(f"The following error occurred: {str(e)}")
Exception: The following error occurred: MONGODB_URI is not set

During handling of the above exception, another exception occurred:

Traceback (most recent call last):
  File "/home/airflow/.local/lib/python3.12/site-packages/airflow/task/task_runner/standard_task_runner.py", line 117, in _start_by_fork
    ret = args.func(args, dag=self.dag)
          ^^^^^^^^^^^^^^^^^^^^^^^^^^^^^
  File "/home/airflow/.local/lib/python3.12/site-packages/airflow/cli/cli_config.py", line 49, in command
    return func(*args, **kwargs)
           ^^^^^^^^^^^^^^^^^^^^^
  File "/home/airflow/.local/lib/python3.12/site-packages/airflow/utils/cli.py", line 116, in wrapper
    return f(*args, **kwargs)
           ^^^^^^^^^^^^^^^^^^
  File "/home/airflow/.local/lib/python3.12/site-packages/airflow/cli/commands/task_command.py", line 483, in task_run
    task_return_code = _run_task_by_selected_method(args, _dag, ti)
                       ^^^^^^^^^^^^^^^^^^^^^^^^^^^^^^^^^^^^^^^^^^^^
  File "/home/airflow/.local/lib/python3.12/site-packages/airflow/cli/commands/task_command.py", line 256, in _run_task_by_selected_method
    return _run_raw_task(args, ti)
           ^^^^^^^^^^^^^^^^^^^^^^^
  File "/home/airflow/.local/lib/python3.12/site-packages/airflow/cli/commands/task_command.py", line 341, in _run_raw_task
    return ti._run_raw_task(
           ^^^^^^^^^^^^^^^^^
  File "/home/airflow/.local/lib/python3.12/site-packages/airflow/utils/session.py", line 97, in wrapper
    return func(*args, session=session, **kwargs)
           ^^^^^^^^^^^^^^^^^^^^^^^^^^^^^^^^^^^^^^
  File "/home/airflow/.local/lib/python3.12/site-packages/airflow/models/taskinstance.py", line 3005, in _run_raw_task
    return _run_raw_task(
           ^^^^^^^^^^^^^^
  File "/home/airflow/.local/lib/python3.12/site-packages/airflow/models/taskinstance.py", line 273, in _run_raw_task
    TaskInstance._execute_task_with_callbacks(
  File "/home/airflow/.local/lib/python3.12/site-packages/airflow/models/taskinstance.py", line 3159, in _execute_task_with_callbacks
    result = self._execute_task(context, task_orig)
             ^^^^^^^^^^^^^^^^^^^^^^^^^^^^^^^^^^^^^^
  File "/home/airflow/.local/lib/python3.12/site-packages/airflow/models/taskinstance.py", line 3183, in _execute_task
    return _execute_task(self, context, task_orig)
           ^^^^^^^^^^^^^^^^^^^^^^^^^^^^^^^^^^^^^^^
  File "/home/airflow/.local/lib/python3.12/site-packages/airflow/models/taskinstance.py", line 767, in _execute_task
    result = _execute_callable(context=context, **execute_callable_kwargs)
             ^^^^^^^^^^^^^^^^^^^^^^^^^^^^^^^^^^^^^^^^^^^^^^^^^^^^^^^^^^^^^
  File "/home/airflow/.local/lib/python3.12/site-packages/airflow/models/taskinstance.py", line 733, in _execute_callable
    return ExecutionCallableRunner(
           ^^^^^^^^^^^^^^^^^^^^^^^^
  File "/home/airflow/.local/lib/python3.12/site-packages/airflow/utils/operator_helpers.py", line 252, in run
    return self.func(*args, **kwargs)
           ^^^^^^^^^^^^^^^^^^^^^^^^^^
  File "/home/airflow/.local/lib/python3.12/site-packages/airflow/models/baseoperator.py", line 422, in wrapper
    return func(self, *args, **kwargs)
           ^^^^^^^^^^^^^^^^^^^^^^^^^^^
  File "/home/airflow/.local/lib/python3.12/site-packages/airflow/operators/python.py", line 238, in execute
    return_value = self.execute_callable()
                   ^^^^^^^^^^^^^^^^^^^^^^^
  File "/home/airflow/.local/lib/python3.12/site-packages/airflow/operators/python.py", line 256, in execute_callable
    return runner.run(*self.op_args, **self.op_kwargs)
           ^^^^^^^^^^^^^^^^^^^^^^^^^^^^^^^^^^^^^^^^^^^
  File "/home/airflow/.local/lib/python3.12/site-packages/airflow/utils/operator_helpers.py", line 252, in run
    return self.func(*args, **kwargs)
           ^^^^^^^^^^^^^^^^^^^^^^^^^^
  File "/opt/airflow/dags/idp.py", line 42, in fetch_from_mongo
    client.close()  # Close client only after fetching data
    ^^^^^^
UnboundLocalError: cannot access local variable 'client' where it is not associated with a value
[2025-02-04T14:00:09.026+0000] {local_task_job_runner.py:266} INFO - Task exited with return code 1
[2025-02-04T14:00:09.048+0000] {taskinstance.py:3895} INFO - 0 downstream tasks scheduled from follow-on schedule check
[2025-02-04T14:00:09.049+0000] {local_task_job_runner.py:245} INFO - ::endgroup::
