[2025-02-22T03:24:33.683+0000] {local_task_job_runner.py:123} INFO - ::group::Pre task execution logs
[2025-02-22T03:24:33.694+0000] {taskinstance.py:2613} INFO - Dependencies all met for dep_context=non-requeueable deps ti=<TaskInstance: idp.rabbitmq_consumer scheduled__2025-02-21T00:00:00+00:00 [queued]>
[2025-02-22T03:24:33.700+0000] {taskinstance.py:2613} INFO - Dependencies all met for dep_context=requeueable deps ti=<TaskInstance: idp.rabbitmq_consumer scheduled__2025-02-21T00:00:00+00:00 [queued]>
[2025-02-22T03:24:33.701+0000] {taskinstance.py:2866} INFO - Starting attempt 1 of 2
[2025-02-22T03:24:33.714+0000] {taskinstance.py:2889} INFO - Executing <Task(PythonOperator): rabbitmq_consumer> on 2025-02-21 00:00:00+00:00
[2025-02-22T03:24:33.725+0000] {warnings.py:112} WARNING - /home/***/.local/lib/python3.12/site-packages/***/task/task_runner/standard_task_runner.py:70: DeprecationWarning: This process (pid=68) is multi-threaded, use of fork() may lead to deadlocks in the child.
  pid = os.fork()

[2025-02-22T03:24:33.726+0000] {standard_task_runner.py:72} INFO - Started process 69 to run task
[2025-02-22T03:24:33.727+0000] {standard_task_runner.py:104} INFO - Running: ['***', 'tasks', 'run', 'idp', 'rabbitmq_consumer', 'scheduled__2025-02-21T00:00:00+00:00', '--job-id', '352', '--raw', '--subdir', 'DAGS_FOLDER/idp.py', '--cfg-path', '/tmp/tmp8vj5k2a9']
[2025-02-22T03:24:33.727+0000] {standard_task_runner.py:105} INFO - Job 352: Subtask rabbitmq_consumer
[2025-02-22T03:24:33.777+0000] {task_command.py:467} INFO - Running <TaskInstance: idp.rabbitmq_consumer scheduled__2025-02-21T00:00:00+00:00 [running]> on host 3aa1f743f988
[2025-02-22T03:24:33.856+0000] {taskinstance.py:3132} INFO - Exporting env vars: AIRFLOW_CTX_DAG_OWNER='***' AIRFLOW_CTX_DAG_ID='idp' AIRFLOW_CTX_TASK_ID='rabbitmq_consumer' AIRFLOW_CTX_EXECUTION_DATE='2025-02-21T00:00:00+00:00' AIRFLOW_CTX_TRY_NUMBER='1' AIRFLOW_CTX_DAG_RUN_ID='scheduled__2025-02-21T00:00:00+00:00'
[2025-02-22T03:24:33.858+0000] {logging_mixin.py:190} INFO - Task instance is in running state
[2025-02-22T03:24:33.858+0000] {logging_mixin.py:190} INFO -  Previous state of the Task instance: queued
[2025-02-22T03:24:33.858+0000] {logging_mixin.py:190} INFO - Current task name:rabbitmq_consumer state:running start_date:2025-02-22 03:24:33.695650+00:00
[2025-02-22T03:24:33.859+0000] {logging_mixin.py:190} INFO - Dag name:idp and current dag run status:running
[2025-02-22T03:24:33.859+0000] {taskinstance.py:731} INFO - ::endgroup::
[2025-02-22T03:24:33.881+0000] {selector_ioloop_adapter.py:569} ERROR - Address resolution failed: gaierror(-2, 'Name or service not known')
[2025-02-22T03:24:33.883+0000] {connection_workflow.py:799} ERROR - getaddrinfo failed: gaierror(-2, 'Name or service not known').
[2025-02-22T03:24:33.884+0000] {connection_workflow.py:746} ERROR - AMQP connection workflow failed: AMQPConnectionWorkflowFailed: 1 exceptions in all; last exception - gaierror(-2, 'Name or service not known'); first exception - None.
[2025-02-22T03:24:33.884+0000] {connection_workflow.py:723} ERROR - AMQPConnectionWorkflow - reporting failure: AMQPConnectionWorkflowFailed: 1 exceptions in all; last exception - gaierror(-2, 'Name or service not known'); first exception - None
[2025-02-22T03:24:33.885+0000] {blocking_connection.py:450} ERROR - Connection workflow failed: AMQPConnectionWorkflowFailed: 1 exceptions in all; last exception - gaierror(-2, 'Name or service not known'); first exception - None
[2025-02-22T03:24:33.885+0000] {blocking_connection.py:457} ERROR - Error in _create_connection().
Traceback (most recent call last):
  File "/home/airflow/.local/lib/python3.12/site-packages/pika/adapters/blocking_connection.py", line 451, in _create_connection
    raise self._reap_last_connection_workflow_error(error)
  File "/home/airflow/.local/lib/python3.12/site-packages/pika/adapters/utils/selector_ioloop_adapter.py", line 565, in _resolve
    result = socket.getaddrinfo(self._host, self._port, self._family,
             ^^^^^^^^^^^^^^^^^^^^^^^^^^^^^^^^^^^^^^^^^^^^^^^^^^^^^^^^
  File "/usr/local/lib/python3.12/socket.py", line 976, in getaddrinfo
    for res in _socket.getaddrinfo(host, port, family, type, proto, flags):
               ^^^^^^^^^^^^^^^^^^^^^^^^^^^^^^^^^^^^^^^^^^^^^^^^^^^^^^^^^^^
socket.gaierror: [Errno -2] Name or service not known
[2025-02-22T03:24:33.888+0000] {logging_mixin.py:190} INFO - Error in listener: [Errno -2] Name or service not known
[2025-02-22T03:24:33.889+0000] {logging_mixin.py:190} INFO - Listener stopped.
[2025-02-22T03:24:33.889+0000] {python.py:240} INFO - Done. Returned value was: 
[2025-02-22T03:24:33.934+0000] {taskinstance.py:340} INFO - ::group::Post task execution logs
[2025-02-22T03:24:33.934+0000] {taskinstance.py:352} INFO - Marking task as SUCCESS. dag_id=idp, task_id=rabbitmq_consumer, run_id=scheduled__2025-02-21T00:00:00+00:00, execution_date=20250221T000000, start_date=20250222T032433, end_date=20250222T032433
[2025-02-22T03:24:33.943+0000] {logging_mixin.py:190} INFO - Task instance in success state
[2025-02-22T03:24:33.943+0000] {logging_mixin.py:190} INFO -  Previous state of the Task instance: running
[2025-02-22T03:24:33.944+0000] {logging_mixin.py:190} INFO - Dag name:idp queued_at:2025-02-22 03:24:27.563268+00:00
[2025-02-22T03:24:33.944+0000] {logging_mixin.py:190} INFO - Task hostname:3aa1f743f988 operator:PythonOperator
[2025-02-22T03:24:33.992+0000] {local_task_job_runner.py:266} INFO - Task exited with return code 0
[2025-02-22T03:24:34.013+0000] {taskinstance.py:3895} INFO - 1 downstream tasks scheduled from follow-on schedule check
[2025-02-22T03:24:34.015+0000] {local_task_job_runner.py:245} INFO - ::endgroup::
